Workbook
Name _Hlk196835118: '[5]Hằng DT'!#REF!
Name DATA_SALE_YTD: [1]!Table2[#All]
Name PLKhachhang: [2]!Table6[#Data]

Sheet DK đặt hàng
A1: Tên sản phẩm | B1: Giá EXW | C1: Packing/Pallet | D1: Feb.26 | E1: Mar.26 | F1: Apr.26 | G1: May.26 | H1: Jun.26 | I1: Jul.26 | J1: Aug.26 | K1: Sep.26 | L1: Oct.26 | M1: Nov.26 | N1: Dec.26 | O1: Jan.27 | P1: Feb.27 | Q1: Mar.27
A2: Exeol gel 82 500ml | B2: 1.773 | C2: 672 | E2: =SUMIFS(INDEX(NXT!$A:$ZZ, 0, MATCH(TEXT(EDATE(DATEVALUE("1-"&SUBSTITUTE(E$1,".","-")),5),"mmm.yy"), NXT!$1:$1, 0)), NXT!$A:$A, $A2) -> 0 | F2: =SUMIFS(INDEX(NXT!$A:$ZZ, 0, MATCH(TEXT(EDATE(DATEVALUE("1-"&SUBSTITUTE(F$1,".","-")),5),"mmm.yy"), NXT!$1:$1, 0)), NXT!$A:$A, $A2) -> 0 | G2: =SUMIFS(INDEX(NXT!$A:$ZZ, 0, MATCH(TEXT(EDATE(DATEVALUE("1-"&SUBSTITUTE(G$1,".","-")),5),"mmm.yy"), NXT!$1:$1, 0)), NXT!$A:$A, $A2) -> 0 | H2: =SUMIFS(INDEX(NXT!$A:$ZZ, 0, MATCH(TEXT(EDATE(DATEVALUE("1-"&SUBSTITUTE(H$1,".","-")),5),"mmm.yy"), NXT!$1:$1, 0)), NXT!$A:$A, $A2) -> 0 | I2: =SUMIFS(INDEX(NXT!$A:$ZZ, 0, MATCH(TEXT(EDATE(DATEVALUE("1-"&SUBSTITUTE(I$1,".","-")),5),"mmm.yy"), NXT!$1:$1, 0)), NXT!$A:$A, $A2) -> 0 | J2: =SUMIFS(INDEX(NXT!$A:$ZZ, 0, MATCH(TEXT(EDATE(DATEVALUE("1-"&SUBSTITUTE(J$1,".","-")),5),"mmm.yy"), NXT!$1:$1, 0)), NXT!$A:$A, $A2) -> 0 | K2: =SUMIFS(INDEX(NXT!$A:$ZZ, 0, MATCH(TEXT(EDATE(DATEVALUE("1-"&SUBSTITUTE(K$1,".","-")),5),"mmm.yy"), NXT!$1:$1, 0)), NXT!$A:$A, $A2) -> 0 | L2: =SUMIFS(INDEX(NXT!$A:$ZZ, 0, MATCH(TEXT(EDATE(DATEVALUE("1-"&SUBSTITUTE(L$1,".","-")),5),"mmm.yy"), NXT!$1:$1, 0)), NXT!$A:$A, $A2) -> 0 | ... N2: =SUMIFS(INDEX(NXT!$A:$ZZ, 0, MATCH(TEXT(EDATE(DATEVALUE("1-"&SUBSTITUTE(N$1,".","-")),5),"mmm.yy"), NXT!$1:$1, 0)), NXT!$A:$A, $A2) -> 0
A3: Exeol gel 82 1L | B3: 3.26 | C3: 288 | E3: =SUMIFS(INDEX(NXT!$A:$ZZ, 0, MATCH(TEXT(EDATE(DATEVALUE("1-"&SUBSTITUTE(E$1,".","-")),5),"mmm.yy"), NXT!$1:$1, 0)), NXT!$A:$A, $A3) -> 0 | F3: =SUMIFS(INDEX(NXT!$A:$ZZ, 0, MATCH(TEXT(EDATE(DATEVALUE("1-"&SUBSTITUTE(F$1,".","-")),5),"mmm.yy"), NXT!$1:$1, 0)), NXT!$A:$A, $A3) -> 0 | G3: =SUMIFS(INDEX(NXT!$A:$ZZ, 0, MATCH(TEXT(EDATE(DATEVALUE("1-"&SUBSTITUTE(G$1,".","-")),5),"mmm.yy"), NXT!$1:$1, 0)), NXT!$A:$A, $A3) -> 0 | H3: =SUMIFS(INDEX(NXT!$A:$ZZ, 0, MATCH(TEXT(EDATE(DATEVALUE("1-"&SUBSTITUTE(H$1,".","-")),5),"mmm.yy"), NXT!$1:$1, 0)), NXT!$A:$A, $A3) -> 0 | I3: =SUMIFS(INDEX(NXT!$A:$ZZ, 0, MATCH(TEXT(EDATE(DATEVALUE("1-"&SUBSTITUTE(I$1,".","-")),5),"mmm.yy"), NXT!$1:$1, 0)), NXT!$A:$A, $A3) -> 0 | J3: =SUMIFS(INDEX(NXT!$A:$ZZ, 0, MATCH(TEXT(EDATE(DATEVALUE("1-"&SUBSTITUTE(J$1,".","-")),5),"mmm.yy"), NXT!$1:$1, 0)), NXT!$A:$A, $A3) -> 0 | K3: =SUMIFS(INDEX(NXT!$A:$ZZ, 0, MATCH(TEXT(EDATE(DATEVALUE("1-"&SUBSTITUTE(K$1,".","-")),5),"mmm.yy"), NXT!$1:$1, 0)), NXT!$A:$A, $A3) -> 0 | L3: =SUMIFS(INDEX(NXT!$A:$ZZ, 0, MATCH(TEXT(EDATE(DATEVALUE("1-"&SUBSTITUTE(L$1,".","-")),5),"mmm.yy"), NXT!$1:$1, 0)), NXT!$A:$A, $A3) -> 0 | ... N3: =SUMIFS(INDEX(NXT!$A:$ZZ, 0, MATCH(TEXT(EDATE(DATEVALUE("1-"&SUBSTITUTE(N$1,".","-")),5),"mmm.yy"), NXT!$1:$1, 0)), NXT!$A:$A, $A3) -> 0
A4: Exeol gel 82 1L Airless | B4: 3.15 | C4: 324 | E4: =SUMIFS(INDEX(NXT!$A:$ZZ, 0, MATCH(TEXT(EDATE(DATEVALUE("1-"&SUBSTITUTE(E$1,".","-")),5),"mmm.yy"), NXT!$1:$1, 0)), NXT!$A:$A, $A4) -> 0 | F4: =SUMIFS(INDEX(NXT!$A:$ZZ, 0, MATCH(TEXT(EDATE(DATEVALUE("1-"&SUBSTITUTE(F$1,".","-")),5),"mmm.yy"), NXT!$1:$1, 0)), NXT!$A:$A, $A4) -> 0 | G4: =SUMIFS(INDEX(NXT!$A:$ZZ, 0, MATCH(TEXT(EDATE(DATEVALUE("1-"&SUBSTITUTE(G$1,".","-")),5),"mmm.yy"), NXT!$1:$1, 0)), NXT!$A:$A, $A4) -> 0 | H4: =SUMIFS(INDEX(NXT!$A:$ZZ, 0, MATCH(TEXT(EDATE(DATEVALUE("1-"&SUBSTITUTE(H$1,".","-")),5),"mmm.yy"), NXT!$1:$1, 0)), NXT!$A:$A, $A4) -> 0 | I4: =SUMIFS(INDEX(NXT!$A:$ZZ, 0, MATCH(TEXT(EDATE(DATEVALUE("1-"&SUBSTITUTE(I$1,".","-")),5),"mmm.yy"), NXT!$1:$1, 0)), NXT!$A:$A, $A4) -> 0 | J4: =SUMIFS(INDEX(NXT!$A:$ZZ, 0, MATCH(TEXT(EDATE(DATEVALUE("1-"&SUBSTITUTE(J$1,".","-")),5),"mmm.yy"), NXT!$1:$1, 0)), NXT!$A:$A, $A4) -> 0 | K4: =SUMIFS(INDEX(NXT!$A:$ZZ, 0, MATCH(TEXT(EDATE(DATEVALUE("1-"&SUBSTITUTE(K$1,".","-")),5),"mmm.yy"), NXT!$1:$1, 0)), NXT!$A:$A, $A4) -> 0 | L4: =SUMIFS(INDEX(NXT!$A:$ZZ, 0, MATCH(TEXT(EDATE(DATEVALUE("1-"&SUBSTITUTE(L$1,".","-")),5),"mmm.yy"), NXT!$1:$1, 0)), NXT!$A:$A, $A4) -> 0 | ... N4: =SUMIFS(INDEX(NXT!$A:$ZZ, 0, MATCH(TEXT(EDATE(DATEVALUE("1-"&SUBSTITUTE(N$1,".","-")),5),"mmm.yy"), NXT!$1:$1, 0)), NXT!$A:$A, $A4) -> 0
A5: Exeol scrub 4% 1L | B5: 3.374 | C5: 288 | E5: =SUMIFS(INDEX(NXT!$A:$ZZ, 0, MATCH(TEXT(EDATE(DATEVALUE("1-"&SUBSTITUTE(E$1,".","-")),5),"mmm.yy"), NXT!$1:$1, 0)), NXT!$A:$A, $A5) -> 0 | F5: =SUMIFS(INDEX(NXT!$A:$ZZ, 0, MATCH(TEXT(EDATE(DATEVALUE("1-"&SUBSTITUTE(F$1,".","-")),5),"mmm.yy"), NXT!$1:$1, 0)), NXT!$A:$A, $A5) -> 0 | G5: =SUMIFS(INDEX(NXT!$A:$ZZ, 0, MATCH(TEXT(EDATE(DATEVALUE("1-"&SUBSTITUTE(G$1,".","-")),5),"mmm.yy"), NXT!$1:$1, 0)), NXT!$A:$A, $A5) -> 0 | H5: =SUMIFS(INDEX(NXT!$A:$ZZ, 0, MATCH(TEXT(EDATE(DATEVALUE("1-"&SUBSTITUTE(H$1,".","-")),5),"mmm.yy"), NXT!$1:$1, 0)), NXT!$A:$A, $A5) -> 0 | I5: =SUMIFS(INDEX(NXT!$A:$ZZ, 0, MATCH(TEXT(EDATE(DATEVALUE("1-"&SUBSTITUTE(I$1,".","-")),5),"mmm.yy"), NXT!$1:$1, 0)), NXT!$A:$A, $A5) -> 0 | J5: =SUMIFS(INDEX(NXT!$A:$ZZ, 0, MATCH(TEXT(EDATE(DATEVALUE("1-"&SUBSTITUTE(J$1,".","-")),5),"mmm.yy"), NXT!$1:$1, 0)), NXT!$A:$A, $A5) -> 0 | K5: =SUMIFS(INDEX(NXT!$A:$ZZ, 0, MATCH(TEXT(EDATE(DATEVALUE("1-"&SUBSTITUTE(K$1,".","-")),5),"mmm.yy"), NXT!$1:$1, 0)), NXT!$A:$A, $A5) -> 0 | L5: =SUMIFS(INDEX(NXT!$A:$ZZ, 0, MATCH(TEXT(EDATE(DATEVALUE("1-"&SUBSTITUTE(L$1,".","-")),5),"mmm.yy"), NXT!$1:$1, 0)), NXT!$A:$A, $A5) -> 0 | ... N5: =SUMIFS(INDEX(NXT!$A:$ZZ, 0, MATCH(TEXT(EDATE(DATEVALUE("1-"&SUBSTITUTE(N$1,".","-")),5),"mmm.yy"), NXT!$1:$1, 0)), NXT!$A:$A, $A5) -> 0
A6: Exeol scrub 4% 500ml | B6: 2.1 | C6: 672 | E6: =SUMIFS(INDEX(NXT!$A:$ZZ, 0, MATCH(TEXT(EDATE(DATEVALUE("1-"&SUBSTITUTE(E$1,".","-")),5),"mmm.yy"), NXT!$1:$1, 0)), NXT!$A:$A, $A6) -> 0 | F6: =SUMIFS(INDEX(NXT!$A:$ZZ, 0, MATCH(TEXT(EDATE(DATEVALUE("1-"&SUBSTITUTE(F$1,".","-")),5),"mmm.yy"), NXT!$1:$1, 0)), NXT!$A:$A, $A6) -> 0 | G6: =SUMIFS(INDEX(NXT!$A:$ZZ, 0, MATCH(TEXT(EDATE(DATEVALUE("1-"&SUBSTITUTE(G$1,".","-")),5),"mmm.yy"), NXT!$1:$1, 0)), NXT!$A:$A, $A6) -> 0 | H6: =SUMIFS(INDEX(NXT!$A:$ZZ, 0, MATCH(TEXT(EDATE(DATEVALUE("1-"&SUBSTITUTE(H$1,".","-")),5),"mmm.yy"), NXT!$1:$1, 0)), NXT!$A:$A, $A6) -> 0 | I6: =SUMIFS(INDEX(NXT!$A:$ZZ, 0, MATCH(TEXT(EDATE(DATEVALUE("1-"&SUBSTITUTE(I$1,".","-")),5),"mmm.yy"), NXT!$1:$1, 0)), NXT!$A:$A, $A6) -> 0 | J6: =SUMIFS(INDEX(NXT!$A:$ZZ, 0, MATCH(TEXT(EDATE(DATEVALUE("1-"&SUBSTITUTE(J$1,".","-")),5),"mmm.yy"), NXT!$1:$1, 0)), NXT!$A:$A, $A6) -> 0 | K6: =SUMIFS(INDEX(NXT!$A:$ZZ, 0, MATCH(TEXT(EDATE(DATEVALUE("1-"&SUBSTITUTE(K$1,".","-")),5),"mmm.yy"), NXT!$1:$1, 0)), NXT!$A:$A, $A6) -> 0 | L6: =SUMIFS(INDEX(NXT!$A:$ZZ, 0, MATCH(TEXT(EDATE(DATEVALUE("1-"&SUBSTITUTE(L$1,".","-")),5),"mmm.yy"), NXT!$1:$1, 0)), NXT!$A:$A, $A6) -> 0 | ... N6: =SUMIFS(INDEX(NXT!$A:$ZZ, 0, MATCH(TEXT(EDATE(DATEVALUE("1-"&SUBSTITUTE(N$1,".","-")),5),"mmm.yy"), NXT!$1:$1, 0)), NXT!$A:$A, $A6) -> 0
A7: Exeol surf 30 1L | B7: 3.906 | C7: 288 | E7: =SUMIFS(INDEX(NXT!$A:$ZZ, 0, MATCH(TEXT(EDATE(DATEVALUE("1-"&SUBSTITUTE(E$1,".","-")),5),"mmm.yy"), NXT!$1:$1, 0)), NXT!$A:$A, $A7) -> 0 | F7: =SUMIFS(INDEX(NXT!$A:$ZZ, 0, MATCH(TEXT(EDATE(DATEVALUE("1-"&SUBSTITUTE(F$1,".","-")),5),"mmm.yy"), NXT!$1:$1, 0)), NXT!$A:$A, $A7) -> 864 | G7: =SUMIFS(INDEX(NXT!$A:$ZZ, 0, MATCH(TEXT(EDATE(DATEVALUE("1-"&SUBSTITUTE(G$1,".","-")),5),"mmm.yy"), NXT!$1:$1, 0)), NXT!$A:$A, $A7) -> 288 | H7: =SUMIFS(INDEX(NXT!$A:$ZZ, 0, MATCH(TEXT(EDATE(DATEVALUE("1-"&SUBSTITUTE(H$1,".","-")),5),"mmm.yy"), NXT!$1:$1, 0)), NXT!$A:$A, $A7) -> 0 | I7: =SUMIFS(INDEX(NXT!$A:$ZZ, 0, MATCH(TEXT(EDATE(DATEVALUE("1-"&SUBSTITUTE(I$1,".","-")),5),"mmm.yy"), NXT!$1:$1, 0)), NXT!$A:$A, $A7) -> 864 | J7: =SUMIFS(INDEX(NXT!$A:$ZZ, 0, MATCH(TEXT(EDATE(DATEVALUE("1-"&SUBSTITUTE(J$1,".","-")),5),"mmm.yy"), NXT!$1:$1, 0)), NXT!$A:$A, $A7) -> 0 | K7: =SUMIFS(INDEX(NXT!$A:$ZZ, 0, MATCH(TEXT(EDATE(DATEVALUE("1-"&SUBSTITUTE(K$1,".","-")),5),"mmm.yy"), NXT!$1:$1, 0)), NXT!$A:$A, $A7) -> 1440 | L7: =SUMIFS(INDEX(NXT!$A:$ZZ, 0, MATCH(TEXT(EDATE(DATEVALUE("1-"&SUBSTITUTE(L$1,".","-")),5),"mmm.yy"), NXT!$1:$1, 0)), NXT!$A:$A, $A7) -> 0 | ... N7: =SUMIFS(INDEX(NXT!$A:$ZZ, 0, MATCH(TEXT(EDATE(DATEVALUE("1-"&SUBSTITUTE(N$1,".","-")),5),"mmm.yy"), NXT!$1:$1, 0)), NXT!$A:$A, $A7) -> 0
A8: Exeol surf 30 5L | B8: 10.76 | C8: 96 | E8: =SUMIFS(INDEX(NXT!$A:$ZZ, 0, MATCH(TEXT(EDATE(DATEVALUE("1-"&SUBSTITUTE(E$1,".","-")),5),"mmm.yy"), NXT!$1:$1, 0)), NXT!$A:$A, $A8) -> 0 | F8: =SUMIFS(INDEX(NXT!$A:$ZZ, 0, MATCH(TEXT(EDATE(DATEVALUE("1-"&SUBSTITUTE(F$1,".","-")),5),"mmm.yy"), NXT!$1:$1, 0)), NXT!$A:$A, $A8) -> 0 | G8: =SUMIFS(INDEX(NXT!$A:$ZZ, 0, MATCH(TEXT(EDATE(DATEVALUE("1-"&SUBSTITUTE(G$1,".","-")),5),"mmm.yy"), NXT!$1:$1, 0)), NXT!$A:$A, $A8) -> 0 | H8: =SUMIFS(INDEX(NXT!$A:$ZZ, 0, MATCH(TEXT(EDATE(DATEVALUE("1-"&SUBSTITUTE(H$1,".","-")),5),"mmm.yy"), NXT!$1:$1, 0)), NXT!$A:$A, $A8) -> 0 | I8: =SUMIFS(INDEX(NXT!$A:$ZZ, 0, MATCH(TEXT(EDATE(DATEVALUE("1-"&SUBSTITUTE(I$1,".","-")),5),"mmm.yy"), NXT!$1:$1, 0)), NXT!$A:$A, $A8) -> 0 | J8: =SUMIFS(INDEX(NXT!$A:$ZZ, 0, MATCH(TEXT(EDATE(DATEVALUE("1-"&SUBSTITUTE(J$1,".","-")),5),"mmm.yy"), NXT!$1:$1, 0)), NXT!$A:$A, $A8) -> 0 | K8: =SUMIFS(INDEX(NXT!$A:$ZZ, 0, MATCH(TEXT(EDATE(DATEVALUE("1-"&SUBSTITUTE(K$1,".","-")),5),"mmm.yy"), NXT!$1:$1, 0)), NXT!$A:$A, $A8) -> 0 | L8: =SUMIFS(INDEX(NXT!$A:$ZZ, 0, MATCH(TEXT(EDATE(DATEVALUE("1-"&SUBSTITUTE(L$1,".","-")),5),"mmm.yy"), NXT!$1:$1, 0)), NXT!$A:$A, $A8) -> 0 | ... N8: =SUMIFS(INDEX(NXT!$A:$ZZ, 0, MATCH(TEXT(EDATE(DATEVALUE("1-"&SUBSTITUTE(N$1,".","-")),5),"mmm.yy"), NXT!$1:$1, 0)), NXT!$A:$A, $A8) -> 0
A9: Exeol floor 1L | B9: 4.59 | C9: 252 | E9: =SUMIFS(INDEX(NXT!$A:$ZZ, 0, MATCH(TEXT(EDATE(DATEVALUE("1-"&SUBSTITUTE(E$1,".","-")),5),"mmm.yy"), NXT!$1:$1, 0)), NXT!$A:$A, $A9) -> 0 | F9: =SUMIFS(INDEX(NXT!$A:$ZZ, 0, MATCH(TEXT(EDATE(DATEVALUE("1-"&SUBSTITUTE(F$1,".","-")),5),"mmm.yy"), NXT!$1:$1, 0)), NXT!$A:$A, $A9) -> 0 | G9: =SUMIFS(INDEX(NXT!$A:$ZZ, 0, MATCH(TEXT(EDATE(DATEVALUE("1-"&SUBSTITUTE(G$1,".","-")),5),"mmm.yy"), NXT!$1:$1, 0)), NXT!$A:$A, $A9) -> 0 | H9: =SUMIFS(INDEX(NXT!$A:$ZZ, 0, MATCH(TEXT(EDATE(DATEVALUE("1-"&SUBSTITUTE(H$1,".","-")),5),"mmm.yy"), NXT!$1:$1, 0)), NXT!$A:$A, $A9) -> 0 | I9: =SUMIFS(INDEX(NXT!$A:$ZZ, 0, MATCH(TEXT(EDATE(DATEVALUE("1-"&SUBSTITUTE(I$1,".","-")),5),"mmm.yy"), NXT!$1:$1, 0)), NXT!$A:$A, $A9) -> 0 | J9: =SUMIFS(INDEX(NXT!$A:$ZZ, 0, MATCH(TEXT(EDATE(DATEVALUE("1-"&SUBSTITUTE(J$1,".","-")),5),"mmm.yy"), NXT!$1:$1, 0)), NXT!$A:$A, $A9) -> 0 | K9: =SUMIFS(INDEX(NXT!$A:$ZZ, 0, MATCH(TEXT(EDATE(DATEVALUE("1-"&SUBSTITUTE(K$1,".","-")),5),"mmm.yy"), NXT!$1:$1, 0)), NXT!$A:$A, $A9) -> 0 | L9: =SUMIFS(INDEX(NXT!$A:$ZZ, 0, MATCH(TEXT(EDATE(DATEVALUE("1-"&SUBSTITUTE(L$1,".","-")),5),"mmm.yy"), NXT!$1:$1, 0)), NXT!$A:$A, $A9) -> 0 | ... N9: =SUMIFS(INDEX(NXT!$A:$ZZ, 0, MATCH(TEXT(EDATE(DATEVALUE("1-"&SUBSTITUTE(N$1,".","-")),5),"mmm.yy"), NXT!$1:$1, 0)), NXT!$A:$A, $A9) -> 0
A10: Exeol floor 5L | B10: 17.74 | C10: 96 | E10: =SUMIFS(INDEX(NXT!$A:$ZZ, 0, MATCH(TEXT(EDATE(DATEVALUE("1-"&SUBSTITUTE(E$1,".","-")),5),"mmm.yy"), NXT!$1:$1, 0)), NXT!$A:$A, $A10) -> 0 | F10: =SUMIFS(INDEX(NXT!$A:$ZZ, 0, MATCH(TEXT(EDATE(DATEVALUE("1-"&SUBSTITUTE(F$1,".","-")),5),"mmm.yy"), NXT!$1:$1, 0)), NXT!$A:$A, $A10) -> 0 | G10: =SUMIFS(INDEX(NXT!$A:$ZZ, 0, MATCH(TEXT(EDATE(DATEVALUE("1-"&SUBSTITUTE(G$1,".","-")),5),"mmm.yy"), NXT!$1:$1, 0)), NXT!$A:$A, $A10) -> 0 | H10: =SUMIFS(INDEX(NXT!$A:$ZZ, 0, MATCH(TEXT(EDATE(DATEVALUE("1-"&SUBSTITUTE(H$1,".","-")),5),"mmm.yy"), NXT!$1:$1, 0)), NXT!$A:$A, $A10) -> 0 | I10: =SUMIFS(INDEX(NXT!$A:$ZZ, 0, MATCH(TEXT(EDATE(DATEVALUE("1-"&SUBSTITUTE(I$1,".","-")),5),"mmm.yy"), NXT!$1:$1, 0)), NXT!$A:$A, $A10) -> 0 | J10: =SUMIFS(INDEX(NXT!$A:$ZZ, 0, MATCH(TEXT(EDATE(DATEVALUE("1-"&SUBSTITUTE(J$1,".","-")),5),"mmm.yy"), NXT!$1:$1, 0)), NXT!$A:$A, $A10) -> 0 | K10: =SUMIFS(INDEX(NXT!$A:$ZZ, 0, MATCH(TEXT(EDATE(DATEVALUE("1-"&SUBSTITUTE(K$1,".","-")),5),"mmm.yy"), NXT!$1:$1, 0)), NXT!$A:$A, $A10) -> 0 | L10: =SUMIFS(INDEX(NXT!$A:$ZZ, 0, MATCH(TEXT(EDATE(DATEVALUE("1-"&SUBSTITUTE(L$1,".","-")),5),"mmm.yy"), NXT!$1:$1, 0)), NXT!$A:$A, $A10) -> 0 | ... N10: =SUMIFS(INDEX(NXT!$A:$ZZ, 0, MATCH(TEXT(EDATE(DATEVALUE("1-"&SUBSTITUTE(N$1,".","-")),5),"mmm.yy"), NXT!$1:$1, 0)), NXT!$A:$A, $A10) -> 0
A11: Exeol surf optimal 750ml | B11: 3.49 | C11: 360 | E11: =SUMIFS(INDEX(NXT!$A:$ZZ, 0, MATCH(TEXT(EDATE(DATEVALUE("1-"&SUBSTITUTE(E$1,".","-")),5),"mmm.yy"), NXT!$1:$1, 0)), NXT!$A:$A, $A11) -> 360 | F11: =SUMIFS(INDEX(NXT!$A:$ZZ, 0, MATCH(TEXT(EDATE(DATEVALUE("1-"&SUBSTITUTE(F$1,".","-")),5),"mmm.yy"), NXT!$1:$1, 0)), NXT!$A:$A, $A11) -> 0 | G11: =SUMIFS(INDEX(NXT!$A:$ZZ, 0, MATCH(TEXT(EDATE(DATEVALUE("1-"&SUBSTITUTE(G$1,".","-")),5),"mmm.yy"), NXT!$1:$1, 0)), NXT!$A:$A, $A11) -> 1080 | H11: =SUMIFS(INDEX(NXT!$A:$ZZ, 0, MATCH(TEXT(EDATE(DATEVALUE("1-"&SUBSTITUTE(H$1,".","-")),5),"mmm.yy"), NXT!$1:$1, 0)), NXT!$A:$A, $A11) -> 0 | I11: =SUMIFS(INDEX(NXT!$A:$ZZ, 0, MATCH(TEXT(EDATE(DATEVALUE("1-"&SUBSTITUTE(I$1,".","-")),5),"mmm.yy"), NXT!$1:$1, 0)), NXT!$A:$A, $A11) -> 0 | J11: =SUMIFS(INDEX(NXT!$A:$ZZ, 0, MATCH(TEXT(EDATE(DATEVALUE("1-"&SUBSTITUTE(J$1,".","-")),5),"mmm.yy"), NXT!$1:$1, 0)), NXT!$A:$A, $A11) -> 0 | K11: =SUMIFS(INDEX(NXT!$A:$ZZ, 0, MATCH(TEXT(EDATE(DATEVALUE("1-"&SUBSTITUTE(K$1,".","-")),5),"mmm.yy"), NXT!$1:$1, 0)), NXT!$A:$A, $A11) -> 1080 | L11: =SUMIFS(INDEX(NXT!$A:$ZZ, 0, MATCH(TEXT(EDATE(DATEVALUE("1-"&SUBSTITUTE(L$1,".","-")),5),"mmm.yy"), NXT!$1:$1, 0)), NXT!$A:$A, $A11) -> 0 | ... N11: =SUMIFS(INDEX(NXT!$A:$ZZ, 0, MATCH(TEXT(EDATE(DATEVALUE("1-"&SUBSTITUTE(N$1,".","-")),5),"mmm.yy"), NXT!$1:$1, 0)), NXT!$A:$A, $A11) -> 0
A12: Exeol wipe optimal | B12: 3.906 | C12: 360 | E12: =SUMIFS(INDEX(NXT!$A:$ZZ, 0, MATCH(TEXT(EDATE(DATEVALUE("1-"&SUBSTITUTE(E$1,".","-")),5),"mmm.yy"), NXT!$1:$1, 0)), NXT!$A:$A, $A12) -> 360 | F12: =SUMIFS(INDEX(NXT!$A:$ZZ, 0, MATCH(TEXT(EDATE(DATEVALUE("1-"&SUBSTITUTE(F$1,".","-")),5),"mmm.yy"), NXT!$1:$1, 0)), NXT!$A:$A, $A12) -> 0 | G12: =SUMIFS(INDEX(NXT!$A:$ZZ, 0, MATCH(TEXT(EDATE(DATEVALUE("1-"&SUBSTITUTE(G$1,".","-")),5),"mmm.yy"), NXT!$1:$1, 0)), NXT!$A:$A, $A12) -> 0 | H12: =SUMIFS(INDEX(NXT!$A:$ZZ, 0, MATCH(TEXT(EDATE(DATEVALUE("1-"&SUBSTITUTE(H$1,".","-")),5),"mmm.yy"), NXT!$1:$1, 0)), NXT!$A:$A, $A12) -> 0 | I12: =SUMIFS(INDEX(NXT!$A:$ZZ, 0, MATCH(TEXT(EDATE(DATEVALUE("1-"&SUBSTITUTE(I$1,".","-")),5),"mmm.yy"), NXT!$1:$1, 0)), NXT!$A:$A, $A12) -> 720 | J12: =SUMIFS(INDEX(NXT!$A:$ZZ, 0, MATCH(TEXT(EDATE(DATEVALUE("1-"&SUBSTITUTE(J$1,".","-")),5),"mmm.yy"), NXT!$1:$1, 0)), NXT!$A:$A, $A12) -> 0 | K12: =SUMIFS(INDEX(NXT!$A:$ZZ, 0, MATCH(TEXT(EDATE(DATEVALUE("1-"&SUBSTITUTE(K$1,".","-")),5),"mmm.yy"), NXT!$1:$1, 0)), NXT!$A:$A, $A12) -> 0 | L12: =SUMIFS(INDEX(NXT!$A:$ZZ, 0, MATCH(TEXT(EDATE(DATEVALUE("1-"&SUBSTITUTE(L$1,".","-")),5),"mmm.yy"), NXT!$1:$1, 0)), NXT!$A:$A, $A12) -> 0 | ... N12: =SUMIFS(INDEX(NXT!$A:$ZZ, 0, MATCH(TEXT(EDATE(DATEVALUE("1-"&SUBSTITUTE(N$1,".","-")),5),"mmm.yy"), NXT!$1:$1, 0)), NXT!$A:$A, $A12) -> 0
A13: Exeol sept first 1L | B13: 4.27 | C13: 252 | E13: =SUMIFS(INDEX(NXT!$A:$ZZ, 0, MATCH(TEXT(EDATE(DATEVALUE("1-"&SUBSTITUTE(E$1,".","-")),5),"mmm.yy"), NXT!$1:$1, 0)), NXT!$A:$A, $A13) -> 252 | F13: =SUMIFS(INDEX(NXT!$A:$ZZ, 0, MATCH(TEXT(EDATE(DATEVALUE("1-"&SUBSTITUTE(F$1,".","-")),5),"mmm.yy"), NXT!$1:$1, 0)), NXT!$A:$A, $A13) -> 0 | G13: =SUMIFS(INDEX(NXT!$A:$ZZ, 0, MATCH(TEXT(EDATE(DATEVALUE("1-"&SUBSTITUTE(G$1,".","-")),5),"mmm.yy"), NXT!$1:$1, 0)), NXT!$A:$A, $A13) -> 0 | H13: =SUMIFS(INDEX(NXT!$A:$ZZ, 0, MATCH(TEXT(EDATE(DATEVALUE("1-"&SUBSTITUTE(H$1,".","-")),5),"mmm.yy"), NXT!$1:$1, 0)), NXT!$A:$A, $A13) -> 0 | I13: =SUMIFS(INDEX(NXT!$A:$ZZ, 0, MATCH(TEXT(EDATE(DATEVALUE("1-"&SUBSTITUTE(I$1,".","-")),5),"mmm.yy"), NXT!$1:$1, 0)), NXT!$A:$A, $A13) -> 504 | J13: =SUMIFS(INDEX(NXT!$A:$ZZ, 0, MATCH(TEXT(EDATE(DATEVALUE("1-"&SUBSTITUTE(J$1,".","-")),5),"mmm.yy"), NXT!$1:$1, 0)), NXT!$A:$A, $A13) -> 0 | K13: =SUMIFS(INDEX(NXT!$A:$ZZ, 0, MATCH(TEXT(EDATE(DATEVALUE("1-"&SUBSTITUTE(K$1,".","-")),5),"mmm.yy"), NXT!$1:$1, 0)), NXT!$A:$A, $A13) -> 1008 | L13: =SUMIFS(INDEX(NXT!$A:$ZZ, 0, MATCH(TEXT(EDATE(DATEVALUE("1-"&SUBSTITUTE(L$1,".","-")),5),"mmm.yy"), NXT!$1:$1, 0)), NXT!$A:$A, $A13) -> 0 | ... N13: =SUMIFS(INDEX(NXT!$A:$ZZ, 0, MATCH(TEXT(EDATE(DATEVALUE("1-"&SUBSTITUTE(N$1,".","-")),5),"mmm.yy"), NXT!$1:$1, 0)), NXT!$A:$A, $A13) -> 0
... A20: Exeol OPA 5L | B20: 15.21 | C20: 96 | E20: =SUMIFS(INDEX(NXT!$A:$ZZ, 0, MATCH(TEXT(EDATE(DATEVALUE("1-"&SUBSTITUTE(E$1,".","-")),5),"mmm.yy"), NXT!$1:$1, 0)), NXT!$A:$A, $A20) -> 1632 | F20: =SUMIFS(INDEX(NXT!$A:$ZZ, 0, MATCH(TEXT(EDATE(DATEVALUE("1-"&SUBSTITUTE(F$1,".","-")),5),"mmm.yy"), NXT!$1:$1, 0)), NXT!$A:$A, $A20) -> 1536 | G20: =SUMIFS(INDEX(NXT!$A:$ZZ, 0, MATCH(TEXT(EDATE(DATEVALUE("1-"&SUBSTITUTE(G$1,".","-")),5),"mmm.yy"), NXT!$1:$1, 0)), NXT!$A:$A, $A20) -> 96 | H20: =SUMIFS(INDEX(NXT!$A:$ZZ, 0, MATCH(TEXT(EDATE(DATEVALUE("1-"&SUBSTITUTE(H$1,".","-")),5),"mmm.yy"), NXT!$1:$1, 0)), NXT!$A:$A, $A20) -> 2112 | I20: =SUMIFS(INDEX(NXT!$A:$ZZ, 0, MATCH(TEXT(EDATE(DATEVALUE("1-"&SUBSTITUTE(I$1,".","-")),5),"mmm.yy"), NXT!$1:$1, 0)), NXT!$A:$A, $A20) -> 0 | J20: =SUMIFS(INDEX(NXT!$A:$ZZ, 0, MATCH(TEXT(EDATE(DATEVALUE("1-"&SUBSTITUTE(J$1,".","-")),5),"mmm.yy"), NXT!$1:$1, 0)), NXT!$A:$A, $A20) -> 2112 | K20: =SUMIFS(INDEX(NXT!$A:$ZZ, 0, MATCH(TEXT(EDATE(DATEVALUE("1-"&SUBSTITUTE(K$1,".","-")),5),"mmm.yy"), NXT!$1:$1, 0)), NXT!$A:$A, $A20) -> 0 | L20: =SUMIFS(INDEX(NXT!$A:$ZZ, 0, MATCH(TEXT(EDATE(DATEVALUE("1-"&SUBSTITUTE(L$1,".","-")),5),"mmm.yy"), NXT!$1:$1, 0)), NXT!$A:$A, $A20) -> 2112 | ... N20: =SUMIFS(INDEX(NXT!$A:$ZZ, 0, MATCH(TEXT(EDATE(DATEVALUE("1-"&SUBSTITUTE(N$1,".","-")),5),"mmm.yy"), NXT!$1:$1, 0)), NXT!$A:$A, $A20) -> 0
A21: Exeol GTA 2% 5L | B21: 5.97 | C21: 96 | E21: =SUMIFS(INDEX(NXT!$A:$ZZ, 0, MATCH(TEXT(EDATE(DATEVALUE("1-"&SUBSTITUTE(E$1,".","-")),5),"mmm.yy"), NXT!$1:$1, 0)), NXT!$A:$A, $A21) -> 0 | F21: =SUMIFS(INDEX(NXT!$A:$ZZ, 0, MATCH(TEXT(EDATE(DATEVALUE("1-"&SUBSTITUTE(F$1,".","-")),5),"mmm.yy"), NXT!$1:$1, 0)), NXT!$A:$A, $A21) -> 0 | G21: =SUMIFS(INDEX(NXT!$A:$ZZ, 0, MATCH(TEXT(EDATE(DATEVALUE("1-"&SUBSTITUTE(G$1,".","-")),5),"mmm.yy"), NXT!$1:$1, 0)), NXT!$A:$A, $A21) -> 480 | H21: =SUMIFS(INDEX(NXT!$A:$ZZ, 0, MATCH(TEXT(EDATE(DATEVALUE("1-"&SUBSTITUTE(H$1,".","-")),5),"mmm.yy"), NXT!$1:$1, 0)), NXT!$A:$A, $A21) -> 0 | I21: =SUMIFS(INDEX(NXT!$A:$ZZ, 0, MATCH(TEXT(EDATE(DATEVALUE("1-"&SUBSTITUTE(I$1,".","-")),5),"mmm.yy"), NXT!$1:$1, 0)), NXT!$A:$A, $A21) -> 480 | J21: =SUMIFS(INDEX(NXT!$A:$ZZ, 0, MATCH(TEXT(EDATE(DATEVALUE("1-"&SUBSTITUTE(J$1,".","-")),5),"mmm.yy"), NXT!$1:$1, 0)), NXT!$A:$A, $A21) -> 0 | K21: =SUMIFS(INDEX(NXT!$A:$ZZ, 0, MATCH(TEXT(EDATE(DATEVALUE("1-"&SUBSTITUTE(K$1,".","-")),5),"mmm.yy"), NXT!$1:$1, 0)), NXT!$A:$A, $A21) -> 1440 | L21: =SUMIFS(INDEX(NXT!$A:$ZZ, 0, MATCH(TEXT(EDATE(DATEVALUE("1-"&SUBSTITUTE(L$1,".","-")),5),"mmm.yy"), NXT!$1:$1, 0)), NXT!$A:$A, $A21) -> 0 | ... N21: =SUMIFS(INDEX(NXT!$A:$ZZ, 0, MATCH(TEXT(EDATE(DATEVALUE("1-"&SUBSTITUTE(N$1,".","-")),5),"mmm.yy"), NXT!$1:$1, 0)), NXT!$A:$A, $A21) -> 0 | R21: TOTAL 2026 | S21: Target 2026 | T21: GAP
A22: Grand TOTAL VALUE | D22: =SUMPRODUCT($B$2:$B$21,Table3[Feb.26]) -> 0 | E22: =SUMPRODUCT($B$2:$B$21,Table3[Mar.26]) -> 32529.84 | F22: =SUMPRODUCT($B$2:$B$21,Table3[Apr.26]) -> 32520.744 | G22: =SUMPRODUCT($B$2:$B$21,Table3[May.26]) -> 32438.448 | H22: =SUMPRODUCT($B$2:$B$21,Table3[Jun.26]) -> 32123.52 | I22: =SUMPRODUCT($B$2:$B$21,Table3[Jul.26]) -> 30821.544 | J22: =SUMPRODUCT($B$2:$B$21,Table3[Aug.26]) -> 32123.52 | K22: =SUMPRODUCT($B$2:$B$21,Table3[Sep.26]) -> 55742.16 | L22: =SUMPRODUCT($B$2:$B$21,Table3[Oct.26]) -> 32123.52 | M22: =SUMPRODUCT($B$2:$B$21,Table3[Nov.26]) -> 66994.224 | N22: =SUMPRODUCT($B$2:$B$21,Table3[Dec.26]) -> 0 | O22: =SUMPRODUCT($B$2:$B$21,Table3[Jan.27]) -> 0 | P22: =SUMPRODUCT($B$2:$B$21,Table3[Feb.27]) -> 0 | Q22: =SUMPRODUCT($B$2:$B$21,Table3[Mar.27]) -> 0 | R22: =SUM(B22:Q22) -> 347417.52 | S22: 250000 | T22: =S22-R22 -> -97417.52

Sheet NXT
C1: Số Pallet | D1: Feb.26 | G1: Mar.26 | K1: Apr.26 | N1: May.26 | P1: Jun.26 | Q1: Jun.26 | S1: Jul.26 | T1: Jul.26 | V1: Aug.26 | W1: Aug.26 | Y1: Sep.26 | Z1: Sep.26 | AB1: Oct.26 | AC1: Oct.26 | AE1: Nov.26 | AF1: Nov.26 | AH1: Dec.26 | AI1: Dec.26 | AK1: Jan.27 | AL1: Jan.27 | AN1: Feb.27 | AO1: Feb.27 | AQ1: Mar.27 | AR1: Mar.27 | AT1: Apr.27 | AU1: Apr.27 | AW1: May.27 | AX1: May.27
A2: Tên sản phẩm | B2: Tồn kho | C2: Apr.27 | D2: Nhập | E2: Xuất | F2: Tồn | G2: Nhập | H2: Xuất | I2: Tồn | J2: Nhập | K2: Xuất | L2: Tồn | M2: Nhập | N2: Xuất | O2: Tồn | P2: Nhập | Q2: Xuất | R2: Tồn | S2: Nhập | T2: Xuất | U2: Tồn | V2: Nhập | W2: Xuất | X2: Tồn | Y2: Nhập | Z2: Xuất | AA2: Tồn | AB2: Nhập | AC2: Xuất | AD2: Tồn | AE2: Nhập | AF2: Xuất | AG2: Tồn | AH2: Nhập | AI2: Xuất | AJ2: Tồn | AK2: Nhập | AL2: Xuất | AM2: Tồn | AN2: Nhập | AO2: Xuất | AP2: Tồn | AQ2: Nhập | AR2: Xuất | AS2: Tồn | AT2: Nhập | AU2: Xuất | AV2: Tồn | AW2: Nhập | AX2: Xuất | AY2: Tồn
A3: Exeol surf 30 1L | B3: 288 | C3: =INDEX(D3:AZ3, MATCH($C$2, $D$1:$AZ$1, 0))/VLOOKUP(A3,'DK đặt hàng'!A:C,3,FALSE) -> 3 | E3: =SUMIFS([4]!Table2[Feb.26],[4]!Table2[Sản phẩm],NXT!$A3) -> 0 | F3: =B3+D3-E3 -> 288 | H3: 0 | I3: =F3+G3-H3 -> 288 | K3: =SUMIFS(INDEX(Detail!$AA:$AL, 0, MATCH(K$1, Detail!$AA$1:$AL$1, 0)), Detail!$J:$J, $A3) -> 0 | L3: =I3+J3-K3 -> 288 | N3: =SUMIFS(INDEX(Detail!$AA:$AL, 0, MATCH(N$1, Detail!$AA$1:$AL$1, 0)), Detail!$J:$J, $A3) -> 0 | O3: =L3+M3-N3 -> 288 | Q3: =SUMIFS(INDEX(Detail!$AA:$AL, 0, MATCH(Q$1, Detail!$AA$1:$AL$1, 0)), Detail!$J:$J, $A3) -> 28 | R3: =O3+P3-Q3 -> 260 | T3: =SUMIFS(INDEX(Detail!$AA:$AL, 0, MATCH(T$1, Detail!$AA$1:$AL$1, 0)), Detail!$J:$J, $A3) -> 28 | U3: =R3+S3-T3 -> 232 | W3: =SUMIFS(INDEX(Detail!$AA:$AL, 0, MATCH(W$1, Detail!$AA$1:$AL$1, 0)), Detail!$J:$J, $A3) -> 134 | X3: =U3+V3-W3 -> 98 | Y3: =288*3 -> 864 | Z3: =SUMIFS(INDEX(Detail!$AA:$AL, 0, MATCH(Z$1, Detail!$AA$1:$AL$1, 0)), Detail!$J:$J, $A3) -> 235 | AA3: =X3+Y3-Z3 -> 727 | AB3: 288 | AC3: =SUMIFS(INDEX(Detail!$AA:$AL, 0, MATCH(AC$1, Detail!$AA$1:$AL$1, 0)), Detail!$J:$J, $A3) -> 304 | AD3: =AA3+AB3-AC3 -> 711 | AF3: =SUMIFS(INDEX(Detail!$AA:$AL, 0, MATCH(AF$1, Detail!$AA$1:$AL$1, 0)), Detail!$J:$J, $A3) -> 305 | AG3: =AD3+AE3-AF3 -> 406 | AH3: =288*3 -> 864 | AI3: =SUMIFS(INDEX(Detail!$AA:$AL, 0, MATCH(AI$1, Detail!$AA$1:$AL$1, 0)), Detail!$J:$J, $A3) -> 380 | AJ3: =AG3+AH3-AI3 -> 890 | AL3: =SUMIFS(INDEX(Detail!$AA:$AL, 0, MATCH(AL$1, Detail!$AA$1:$AL$1, 0)), Detail!$J:$J, $A3) -> 558 | AM3: =AJ3+AK3-AL3 -> 332 | AN3: =288*5 -> 1440 | AO3: =SUMIFS(INDEX(Detail!$AA:$AL, 0, MATCH(AO$1, Detail!$AA$1:$AL$1, 0)), Detail!$J:$J, $A3) -> 558 | AP3: =AM3+AN3-AO3 -> 1214 | AR3: =SUMIFS(INDEX(Detail!$AA:$AL, 0, MATCH(AR$1, Detail!$AA$1:$AL$1, 0)), Detail!$J:$J, $A3) -> 558 | AS3: =AP3+AQ3-AR3 -> 656 | AT3: =288*3 -> 864 | AU3: =SUMIFS(INDEX(Detail!$AA:$AN, 0, MATCH(AU$1, Detail!$AA$1:$AN$1, 0)), Detail!$J:$J, $A3) -> 558 | AV3: =AS3+AT3-AU3 -> 962 | AX3: =SUMIFS(INDEX(Detail!$AA:$AN, 0, MATCH(AX$1, Detail!$AA$1:$AN$1, 0)), Detail!$J:$J, $A3) -> 558 | AY3: =AV3+AW3-AX3 -> 404
A4: Exeol surf 30 5L | B4: 192 | C4: =INDEX(D4:AZ4, MATCH($C$2, $D$1:$AZ$1, 0))/VLOOKUP(A4,'DK đặt hàng'!A:C,3,FALSE) -> 0 | E4: =SUMIFS([4]!Table2[Feb.26],[4]!Table2[Sản phẩm],NXT!$A4) -> 0 | F4: =B4+D4-E4 -> 192 | H4: 0 | I4: =F4+G4-H4 -> 192 | K4: =SUMIFS(INDEX(Detail!$AA:$AL, 0, MATCH(K$1, Detail!$AA$1:$AL$1, 0)), Detail!$J:$J, $A4) -> 0 | L4: =I4+J4-K4 -> 192 | N4: =SUMIFS(INDEX(Detail!$AA:$AL, 0, MATCH(N$1, Detail!$AA$1:$AL$1, 0)), Detail!$J:$J, $A4) -> 0 | O4: =L4+M4-N4 -> 192 | Q4: =SUMIFS(INDEX(Detail!$AA:$AL, 0, MATCH(Q$1, Detail!$AA$1:$AL$1, 0)), Detail!$J:$J, $A4) -> 0 | R4: =O4+P4-Q4 -> 192 | T4: =SUMIFS(INDEX(Detail!$AA:$AL, 0, MATCH(T$1, Detail!$AA$1:$AL$1, 0)), Detail!$J:$J, $A4) -> 0 | U4: =R4+S4-T4 -> 192 | W4: =SUMIFS(INDEX(Detail!$AA:$AL, 0, MATCH(W$1, Detail!$AA$1:$AL$1, 0)), Detail!$J:$J, $A4) -> 0 | X4: =U4+V4-W4 -> 192 | Z4: =SUMIFS(INDEX(Detail!$AA:$AL, 0, MATCH(Z$1, Detail!$AA$1:$AL$1, 0)), Detail!$J:$J, $A4) -> 0 | AA4: =X4+Y4-Z4 -> 192 | AC4: =SUMIFS(INDEX(Detail!$AA:$AL, 0, MATCH(AC$1, Detail!$AA$1:$AL$1, 0)), Detail!$J:$J, $A4) -> 0 | AD4: =AA4+AB4-AC4 -> 192 | AF4: =SUMIFS(INDEX(Detail!$AA:$AL, 0, MATCH(AF$1, Detail!$AA$1:$AL$1, 0)), Detail!$J:$J, $A4) -> 5 | AG4: =AD4+AE4-AF4 -> 187 | AI4: =SUMIFS(INDEX(Detail!$AA:$AL, 0, MATCH(AI$1, Detail!$AA$1:$AL$1, 0)), Detail!$J:$J, $A4) -> 5 | AJ4: =AG4+AH4-AI4 -> 182 | AL4: =SUMIFS(INDEX(Detail!$AA:$AL, 0, MATCH(AL$1, Detail!$AA$1:$AL$1, 0)), Detail!$J:$J, $A4) -> 5 | AM4: =AJ4+AK4-AL4 -> 177 | AO4: =SUMIFS(INDEX(Detail!$AA:$AL, 0, MATCH(AO$1, Detail!$AA$1:$AL$1, 0)), Detail!$J:$J, $A4) -> 5 | AP4: =AM4+AN4-AO4 -> 172 | AR4: =SUMIFS(INDEX(Detail!$AA:$AL, 0, MATCH(AR$1, Detail!$AA$1:$AL$1, 0)), Detail!$J:$J, $A4) -> 5 | AS4: =AP4+AQ4-AR4 -> 167 | AU4: =SUMIFS(INDEX(Detail!$AA:$AN, 0, MATCH(AU$1, Detail!$AA$1:$AN$1, 0)), Detail!$J:$J, $A4) -> 5 | AV4: =AS4+AT4-AU4 -> 162 | AX4: =SUMIFS(INDEX(Detail!$AA:$AN, 0, MATCH(AX$1, Detail!$AA$1:$AN$1, 0)), Detail!$J:$J, $A4) -> 5 | AY4: =AV4+AW4-AX4 -> 157
A5: Exeol surf optimal 750ml | B5: 360 | C5: =INDEX(D5:AZ5, MATCH($C$2, $D$1:$AZ$1, 0))/VLOOKUP(A5,'DK đặt hàng'!A:C,3,FALSE) -> 1 | E5: =SUMIFS([4]!Table2[Feb.26],[4]!Table2[Sản phẩm],NXT!$A5) -> 0 | F5: =B5+D5-E5 -> 360 | H5: 30 | I5: =F5+G5-H5 -> 330 | K5: =SUMIFS(INDEX(Detail!$AA:$AL, 0, MATCH(K$1, Detail!$AA$1:$AL$1, 0)), Detail!$J:$J, $A5) -> 42 | L5: =I5+J5-K5 -> 288 | N5: =SUMIFS(INDEX(Detail!$AA:$AL, 0, MATCH(N$1, Detail!$AA$1:$AL$1, 0)), Detail!$J:$J, $A5) -> 42 | O5: =L5+M5-N5 -> 246 | Q5: =SUMIFS(INDEX(Detail!$AA:$AL, 0, MATCH(Q$1, Detail!$AA$1:$AL$1, 0)), Detail!$J:$J, $A5) -> 42 | R5: =O5+P5-Q5 -> 204 | T5: =SUMIFS(INDEX(Detail!$AA:$AL, 0, MATCH(T$1, Detail!$AA$1:$AL$1, 0)), Detail!$J:$J, $A5) -> 42 | U5: =R5+S5-T5 -> 162 | V5: 360 | W5: =SUMIFS(INDEX(Detail!$AA:$AL, 0, MATCH(W$1, Detail!$AA$1:$AL$1, 0)), Detail!$J:$J, $A5) -> 59 | X5: =U5+V5-W5 -> 463 | Z5: =SUMIFS(INDEX(Detail!$AA:$AL, 0, MATCH(Z$1, Detail!$AA$1:$AL$1, 0)), Detail!$J:$J, $A5) -> 59 | AA5: =X5+Y5-Z5 -> 404 | AB5: =360*3 -> 1080 | AC5: =SUMIFS(INDEX(Detail!$AA:$AL, 0, MATCH(AC$1, Detail!$AA$1:$AL$1, 0)), Detail!$J:$J, $A5) -> 210 | AD5: =AA5+AB5-AC5 -> 1274 | AF5: =SUMIFS(INDEX(Detail!$AA:$AL, 0, MATCH(AF$1, Detail!$AA$1:$AL$1, 0)), Detail!$J:$J, $A5) -> 227 | AG5: =AD5+AE5-AF5 -> 1047 | AI5: =SUMIFS(INDEX(Detail!$AA:$AL, 0, MATCH(AI$1, Detail!$AA$1:$AL$1, 0)), Detail!$J:$J, $A5) -> 336 | AJ5: =AG5+AH5-AI5 -> 711 | AL5: =SUMIFS(INDEX(Detail!$AA:$AL, 0, MATCH(AL$1, Detail!$AA$1:$AL$1, 0)), Detail!$J:$J, $A5) -> 336 | AM5: =AJ5+AK5-AL5 -> 375 | AN5: =360*3 -> 1080 | AO5: =SUMIFS(INDEX(Detail!$AA:$AL, 0, MATCH(AO$1, Detail!$AA$1:$AL$1, 0)), Detail!$J:$J, $A5) -> 336 | AP5: =AM5+AN5-AO5 -> 1119 | AR5: =SUMIFS(INDEX(Detail!$AA:$AL, 0, MATCH(AR$1, Detail!$AA$1:$AL$1, 0)), Detail!$J:$J, $A5) -> 336 | AS5: =AP5+AQ5-AR5 -> 783 | AT5: =360 -> 360 | AU5: =SUMIFS(INDEX(Detail!$AA:$AN, 0, MATCH(AU$1, Detail!$AA$1:$AN$1, 0)), Detail!$J:$J, $A5) -> 336 | AV5: =AS5+AT5-AU5 -> 807 | AX5: =SUMIFS(INDEX(Detail!$AA:$AN, 0, MATCH(AX$1, Detail!$AA$1:$AN$1, 0)), Detail!$J:$J, $A5) -> 336 | AY5: =AV5+AW5-AX5 -> 471
A6: Exeol wipe optimal | B6: 360 | C6: =INDEX(D6:AZ6, MATCH($C$2, $D$1:$AZ$1, 0))/VLOOKUP(A6,'DK đặt hàng'!A:C,3,FALSE) -> 2 | E6: =SUMIFS([4]!Table2[Feb.26],[4]!Table2[Sản phẩm],NXT!$A6) -> 0 | F6: =B6+D6-E6 -> 360 | H6: 0 | I6: =F6+G6-H6 -> 360 | K6: =SUMIFS(INDEX(Detail!$AA:$AL, 0, MATCH(K$1, Detail!$AA$1:$AL$1, 0)), Detail!$J:$J, $A6) -> 0 | L6: =I6+J6-K6 -> 360 | N6: =SUMIFS(INDEX(Detail!$AA:$AL, 0, MATCH(N$1, Detail!$AA$1:$AL$1, 0)), Detail!$J:$J, $A6) -> 9 | O6: =L6+M6-N6 -> 351 | Q6: =SUMIFS(INDEX(Detail!$AA:$AL, 0, MATCH(Q$1, Detail!$AA$1:$AL$1, 0)), Detail!$J:$J, $A6) -> 9 | R6: =O6+P6-Q6 -> 342 | T6: =SUMIFS(INDEX(Detail!$AA:$AL, 0, MATCH(T$1, Detail!$AA$1:$AL$1, 0)), Detail!$J:$J, $A6) -> 9 | U6: =R6+S6-T6 -> 333 | V6: 360 | W6: =SUMIFS(INDEX(Detail!$AA:$AL, 0, MATCH(W$1, Detail!$AA$1:$AL$1, 0)), Detail!$J:$J, $A6) -> 105 | X6: =U6+V6-W6 -> 588 | Z6: =SUMIFS(INDEX(Detail!$AA:$AL, 0, MATCH(Z$1, Detail!$AA$1:$AL$1, 0)), Detail!$J:$J, $A6) -> 114 | AA6: =X6+Y6-Z6 -> 474 | AC6: =SUMIFS(INDEX(Detail!$AA:$AL, 0, MATCH(AC$1, Detail!$AA$1:$AL$1, 0)), Detail!$J:$J, $A6) -> 114 | AD6: =AA6+AB6-AC6 -> 360 | AF6: =SUMIFS(INDEX(Detail!$AA:$AL, 0, MATCH(AF$1, Detail!$AA$1:$AL$1, 0)), Detail!$J:$J, $A6) -> 115 | AG6: =AD6+AE6-AF6 -> 245 | AH6: =360*2 -> 720 | AI6: =SUMIFS(INDEX(Detail!$AA:$AL, 0, MATCH(AI$1, Detail!$AA$1:$AL$1, 0)), Detail!$J:$J, $A6) -> 115 | AJ6: =AG6+AH6-AI6 -> 850 | AL6: =SUMIFS(INDEX(Detail!$AA:$AL, 0, MATCH(AL$1, Detail!$AA$1:$AL$1, 0)), Detail!$J:$J, $A6) -> 153 | AM6: =AJ6+AK6-AL6 -> 697 | AO6: =SUMIFS(INDEX(Detail!$AA:$AL, 0, MATCH(AO$1, Detail!$AA$1:$AL$1, 0)), Detail!$J:$J, $A6) -> 153 | AP6: =AM6+AN6-AO6 -> 544 | AR6: =SUMIFS(INDEX(Detail!$AA:$AL, 0, MATCH(AR$1, Detail!$AA$1:$AL$1, 0)), Detail!$J:$J, $A6) -> 153 | AS6: =AP6+AQ6-AR6 -> 391 | AT6: =360*2 -> 720 | AU6: =SUMIFS(INDEX(Detail!$AA:$AN, 0, MATCH(AU$1, Detail!$AA$1:$AN$1, 0)), Detail!$J:$J, $A6) -> 153 | AV6: =AS6+AT6-AU6 -> 958 | AX6: =SUMIFS(INDEX(Detail!$AA:$AN, 0, MATCH(AX$1, Detail!$AA$1:$AN$1, 0)), Detail!$J:$J, $A6) -> 153 | AY6: =AV6+AW6-AX6 -> 805
A7: Exeol sept first 1L | B7: 252 | C7: =INDEX(D7:AZ7, MATCH($C$2, $D$1:$AZ$1, 0))/VLOOKUP(A7,'DK đặt hàng'!A:C,3,FALSE) -> 0 | E7: =SUMIFS([4]!Table2[Feb.26],[4]!Table2[Sản phẩm],NXT!$A7) -> 0 | F7: =B7+D7-E7 -> 252 | H7: 0 | I7: =F7+G7-H7 -> 252 | K7: =SUMIFS(INDEX(Detail!$AA:$AL, 0, MATCH(K$1, Detail!$AA$1:$AL$1, 0)), Detail!$J:$J, $A7) -> 0 | L7: =I7+J7-K7 -> 252 | N7: =SUMIFS(INDEX(Detail!$AA:$AL, 0, MATCH(N$1, Detail!$AA$1:$AL$1, 0)), Detail!$J:$J, $A7) -> 0 | O7: =L7+M7-N7 -> 252 | Q7: =SUMIFS(INDEX(Detail!$AA:$AL, 0, MATCH(Q$1, Detail!$AA$1:$AL$1, 0)), Detail!$J:$J, $A7) -> 4 | R7: =O7+P7-Q7 -> 248 | T7: =SUMIFS(INDEX(Detail!$AA:$AL, 0, MATCH(T$1, Detail!$AA$1:$AL$1, 0)), Detail!$J:$J, $A7) -> 4 | U7: =R7+S7-T7 -> 244 | V7: =252 -> 252 | W7: =SUMIFS(INDEX(Detail!$AA:$AL, 0, MATCH(W$1, Detail!$AA$1:$AL$1, 0)), Detail!$J:$J, $A7) -> 35 | X7: =U7+V7-W7 -> 461 | Z7: =SUMIFS(INDEX(Detail!$AA:$AL, 0, MATCH(Z$1, Detail!$AA$1:$AL$1, 0)), Detail!$J:$J, $A7) -> 35 | AA7: =X7+Y7-Z7 -> 426 | AC7: =SUMIFS(INDEX(Detail!$AA:$AL, 0, MATCH(AC$1, Detail!$AA$1:$AL$1, 0)), Detail!$J:$J, $A7) -> 38 | AD7: =AA7+AB7-AC7 -> 388 | AF7: =SUMIFS(INDEX(Detail!$AA:$AL, 0, MATCH(AF$1, Detail!$AA$1:$AL$1, 0)), Detail!$J:$J, $A7) -> 40 | AG7: =AD7+AE7-AF7 -> 348 | AH7: =252*2 -> 504 | AI7: =SUMIFS(INDEX(Detail!$AA:$AL, 0, MATCH(AI$1, Detail!$AA$1:$AL$1, 0)), Detail!$J:$J, $A7) -> 249 | AJ7: =AG7+AH7-AI7 -> 603 | AL7: =SUMIFS(INDEX(Detail!$AA:$AL, 0, MATCH(AL$1, Detail!$AA$1:$AL$1, 0)), Detail!$J:$J, $A7) -> 250 | AM7: =AJ7+AK7-AL7 -> 353 | AN7: =252*4 -> 1008 | AO7: =SUMIFS(INDEX(Detail!$AA:$AL, 0, MATCH(AO$1, Detail!$AA$1:$AL$1, 0)), Detail!$J:$J, $A7) -> 250 | AP7: =AM7+AN7-AO7 -> 1111 | AR7: =SUMIFS(INDEX(Detail!$AA:$AL, 0, MATCH(AR$1, Detail!$AA$1:$AL$1, 0)), Detail!$J:$J, $A7) -> 250 | AS7: =AP7+AQ7-AR7 -> 861 | AU7: =SUMIFS(INDEX(Detail!$AA:$AN, 0, MATCH(AU$1, Detail!$AA$1:$AN$1, 0)), Detail!$J:$J, $A7) -> 250 | AV7: =AS7+AT7-AU7 -> 611 | AX7: =SUMIFS(INDEX(Detail!$AA:$AN, 0, MATCH(AX$1, Detail!$AA$1:$AN$1, 0)), Detail!$J:$J, $A7) -> 250 | AY7: =AV7+AW7-AX7 -> 361
A8: Exeol sept first 5L | B8: 192 | C8: =INDEX(D8:AZ8, MATCH($C$2, $D$1:$AZ$1, 0))/VLOOKUP(A8,'DK đặt hàng'!A:C,3,FALSE) -> 3 | E8: =SUMIFS([4]!Table2[Feb.26],[4]!Table2[Sản phẩm],NXT!$A8) -> 0 | F8: =B8+D8-E8 -> 192 | H8: 0 | I8: =F8+G8-H8 -> 192 | K8: =SUMIFS(INDEX(Detail!$AA:$AL, 0, MATCH(K$1, Detail!$AA$1:$AL$1, 0)), Detail!$J:$J, $A8) -> 0 | L8: =I8+J8-K8 -> 192 | N8: =SUMIFS(INDEX(Detail!$AA:$AL, 0, MATCH(N$1, Detail!$AA$1:$AL$1, 0)), Detail!$J:$J, $A8) -> 7 | O8: =L8+M8-N8 -> 185 | Q8: =SUMIFS(INDEX(Detail!$AA:$AL, 0, MATCH(Q$1, Detail!$AA$1:$AL$1, 0)), Detail!$J:$J, $A8) -> 7 | R8: =O8+P8-Q8 -> 178 | T8: =SUMIFS(INDEX(Detail!$AA:$AL, 0, MATCH(T$1, Detail!$AA$1:$AL$1, 0)), Detail!$J:$J, $A8) -> 7 | U8: =R8+S8-T8 -> 171 | W8: =SUMIFS(INDEX(Detail!$AA:$AL, 0, MATCH(W$1, Detail!$AA$1:$AL$1, 0)), Detail!$J:$J, $A8) -> 22 | X8: =U8+V8-W8 -> 149 | Z8: =SUMIFS(INDEX(Detail!$AA:$AL, 0, MATCH(Z$1, Detail!$AA$1:$AL$1, 0)), Detail!$J:$J, $A8) -> 28 | AA8: =X8+Y8-Z8 -> 121 | AB8: =96*3 -> 288 | AC8: =SUMIFS(INDEX(Detail!$AA:$AL, 0, MATCH(AC$1, Detail!$AA$1:$AL$1, 0)), Detail!$J:$J, $A8) -> 74 | AD8: =AA8+AB8-AC8 -> 335 | AF8: =SUMIFS(INDEX(Detail!$AA:$AL, 0, MATCH(AF$1, Detail!$AA$1:$AL$1, 0)), Detail!$J:$J, $A8) -> 75 | AG8: =AD8+AE8-AF8 -> 260 | AI8: =SUMIFS(INDEX(Detail!$AA:$AL, 0, MATCH(AI$1, Detail!$AA$1:$AL$1, 0)), Detail!$J:$J, $A8) -> 84 | AJ8: =AG8+AH8-AI8 -> 176 | AL8: =SUMIFS(INDEX(Detail!$AA:$AL, 0, MATCH(AL$1, Detail!$AA$1:$AL$1, 0)), Detail!$J:$J, $A8) -> 84 | AM8: =AJ8+AK8-AL8 -> 92 | AN8: =96*4 -> 384 | AO8: =SUMIFS(INDEX(Detail!$AA:$AL, 0, MATCH(AO$1, Detail!$AA$1:$AL$1, 0)), Detail!$J:$J, $A8) -> 84 | AP8: =AM8+AN8-AO8 -> 392 | AR8: =SUMIFS(INDEX(Detail!$AA:$AL, 0, MATCH(AR$1, Detail!$AA$1:$AL$1, 0)), Detail!$J:$J, $A8) -> 84 | AS8: =AP8+AQ8-AR8 -> 308 | AT8: =96*3 -> 288 | AU8: =SUMIFS(INDEX(Detail!$AA:$AN, 0, MATCH(AU$1, Detail!$AA$1:$AN$1, 0)), Detail!$J:$J, $A8) -> 84 | AV8: =AS8+AT8-AU8 -> 512 | AX8: =SUMIFS(INDEX(Detail!$AA:$AN, 0, MATCH(AX$1, Detail!$AA$1:$AN$1, 0)), Detail!$J:$J, $A8) -> 84 | AY8: =AV8+AW8-AX8 -> 428
A9: Exeol rinse matic 5L | B9: 0 | C9: =INDEX(D9:AZ9, MATCH($C$2, $D$1:$AZ$1, 0))/VLOOKUP(A9,'DK đặt hàng'!A:C,3,FALSE) -> 0 | E9: =SUMIFS([4]!Table2[Feb.26],[4]!Table2[Sản phẩm],NXT!$A9) -> 0 | F9: =B9+D9-E9 -> 0 | H9: 0 | I9: =F9+G9-H9 -> 0 | K9: =SUMIFS(INDEX(Detail!$AA:$AL, 0, MATCH(K$1, Detail!$AA$1:$AL$1, 0)), Detail!$J:$J, $A9) -> 0 | L9: =I9+J9-K9 -> 0 | N9: =SUMIFS(INDEX(Detail!$AA:$AL, 0, MATCH(N$1, Detail!$AA$1:$AL$1, 0)), Detail!$J:$J, $A9) -> 0 | O9: =L9+M9-N9 -> 0 | Q9: =SUMIFS(INDEX(Detail!$AA:$AL, 0, MATCH(Q$1, Detail!$AA$1:$AL$1, 0)), Detail!$J:$J, $A9) -> 0 | R9: =O9+P9-Q9 -> 0 | T9: =SUMIFS(INDEX(Detail!$AA:$AL, 0, MATCH(T$1, Detail!$AA$1:$AL$1, 0)), Detail!$J:$J, $A9) -> 0 | U9: =R9+S9-T9 -> 0 | W9: =SUMIFS(INDEX(Detail!$AA:$AL, 0, MATCH(W$1, Detail!$AA$1:$AL$1, 0)), Detail!$J:$J, $A9) -> 0 | X9: =U9+V9-W9 -> 0 | Z9: =SUMIFS(INDEX(Detail!$AA:$AL, 0, MATCH(Z$1, Detail!$AA$1:$AL$1, 0)), Detail!$J:$J, $A9) -> 0 | AA9: =X9+Y9-Z9 -> 0 | AC9: =SUMIFS(INDEX(Detail!$AA:$AL, 0, MATCH(AC$1, Detail!$AA$1:$AL$1, 0)), Detail!$J:$J, $A9) -> 0 | AD9: =AA9+AB9-AC9 -> 0 | AF9: =SUMIFS(INDEX(Detail!$AA:$AL, 0, MATCH(AF$1, Detail!$AA$1:$AL$1, 0)), Detail!$J:$J, $A9) -> 0 | AG9: =AD9+AE9-AF9 -> 0 | AI9: =SUMIFS(INDEX(Detail!$AA:$AL, 0, MATCH(AI$1, Detail!$AA$1:$AL$1, 0)), Detail!$J:$J, $A9) -> 0 | AJ9: =AG9+AH9-AI9 -> 0 | AL9: =SUMIFS(INDEX(Detail!$AA:$AL, 0, MATCH(AL$1, Detail!$AA$1:$AL$1, 0)), Detail!$J:$J, $A9) -> 0 | AM9: =AJ9+AK9-AL9 -> 0 | AO9: =SUMIFS(INDEX(Detail!$AA:$AL, 0, MATCH(AO$1, Detail!$AA$1:$AL$1, 0)), Detail!$J:$J, $A9) -> 0 | AP9: =AM9+AN9-AO9 -> 0 | AR9: =SUMIFS(INDEX(Detail!$AA:$AL, 0, MATCH(AR$1, Detail!$AA$1:$AL$1, 0)), Detail!$J:$J, $A9) -> 0 | AS9: =AP9+AQ9-AR9 -> 0 | AU9: =SUMIFS(INDEX(Detail!$AA:$AN, 0, MATCH(AU$1, Detail!$AA$1:$AN$1, 0)), Detail!$J:$J, $A9) -> 0 | AV9: =AS9+AT9-AU9 -> 0 | AX9: =SUMIFS(INDEX(Detail!$AA:$AN, 0, MATCH(AX$1, Detail!$AA$1:$AN$1, 0)), Detail!$J:$J, $A9) -> 0 | AY9: =AV9+AW9-AX9 -> 0
A10: Exeol clean 4E 1L | B10: 252 | C10: =INDEX(D10:AZ10, MATCH($C$2, $D$1:$AZ$1, 0))/VLOOKUP(A10,'DK đặt hàng'!A:C,3,FALSE) -> 3 | E10: =SUMIFS([4]!Table2[Feb.26],[4]!Table2[Sản phẩm],NXT!$A10) -> 0 | F10: =B10+D10-E10 -> 252 | H10: 0 | I10: =F10+G10-H10 -> 252 | K10: =SUMIFS(INDEX(Detail!$AA:$AL, 0, MATCH(K$1, Detail!$AA$1:$AL$1, 0)), Detail!$J:$J, $A10) -> 0 | L10: =I10+J10-K10 -> 252 | N10: =SUMIFS(INDEX(Detail!$AA:$AL, 0, MATCH(N$1, Detail!$AA$1:$AL$1, 0)), Detail!$J:$J, $A10) -> 0 | O10: =L10+M10-N10 -> 252 | Q10: =SUMIFS(INDEX(Detail!$AA:$AL, 0, MATCH(Q$1, Detail!$AA$1:$AL$1, 0)), Detail!$J:$J, $A10) -> 0 | R10: =O10+P10-Q10 -> 252 | T10: =SUMIFS(INDEX(Detail!$AA:$AL, 0, MATCH(T$1, Detail!$AA$1:$AL$1, 0)), Detail!$J:$J, $A10) -> 0 | U10: =R10+S10-T10 -> 252 | V10: 252 | W10: =SUMIFS(INDEX(Detail!$AA:$AL, 0, MATCH(W$1, Detail!$AA$1:$AL$1, 0)), Detail!$J:$J, $A10) -> 59 | X10: =U10+V10-W10 -> 445 | Z10: =SUMIFS(INDEX(Detail!$AA:$AL, 0, MATCH(Z$1, Detail!$AA$1:$AL$1, 0)), Detail!$J:$J, $A10) -> 95 | AA10: =X10+Y10-Z10 -> 350 | AB10: =252*3 -> 756 | AC10: =SUMIFS(INDEX(Detail!$AA:$AL, 0, MATCH(AC$1, Detail!$AA$1:$AL$1, 0)), Detail!$J:$J, $A10) -> 337 | AD10: =AA10+AB10-AC10 -> 769 | AF10: =SUMIFS(INDEX(Detail!$AA:$AL, 0, MATCH(AF$1, Detail!$AA$1:$AL$1, 0)), Detail!$J:$J, $A10) -> 340 | AG10: =AD10+AE10-AF10 -> 429 | AH10: =252*3 -> 756 | AI10: =SUMIFS(INDEX(Detail!$AA:$AL, 0, MATCH(AI$1, Detail!$AA$1:$AL$1, 0)), Detail!$J:$J, $A10) -> 405 | AJ10: =AG10+AH10-AI10 -> 780 | AL10: =SUMIFS(INDEX(Detail!$AA:$AL, 0, MATCH(AL$1, Detail!$AA$1:$AL$1, 0)), Detail!$J:$J, $A10) -> 405 | AM10: =AJ10+AK10-AL10 -> 375 | AN10: =252*4 -> 1008 | AO10: =SUMIFS(INDEX(Detail!$AA:$AL, 0, MATCH(AO$1, Detail!$AA$1:$AL$1, 0)), Detail!$J:$J, $A10) -> 405 | AP10: =AM10+AN10-AO10 -> 978 | AR10: =SUMIFS(INDEX(Detail!$AA:$AL, 0, MATCH(AR$1, Detail!$AA$1:$AL$1, 0)), Detail!$J:$J, $A10) -> 405 | AS10: =AP10+AQ10-AR10 -> 573 | AT10: =252*3 -> 756 | AU10: =SUMIFS(INDEX(Detail!$AA:$AN, 0, MATCH(AU$1, Detail!$AA$1:$AN$1, 0)), Detail!$J:$J, $A10) -> 405 | AV10: =AS10+AT10-AU10 -> 924 | AX10: =SUMIFS(INDEX(Detail!$AA:$AN, 0, MATCH(AX$1, Detail!$AA$1:$AN$1, 0)), Detail!$J:$J, $A10) -> 405 | AY10: =AV10+AW10-AX10 -> 519
A11: Exeol clean 4E 5L | B11: 192 | C11: =INDEX(D11:AZ11, MATCH($C$2, $D$1:$AZ$1, 0))/VLOOKUP(A11,'DK đặt hàng'!A:C,3,FALSE) -> 4 | E11: =SUMIFS([4]!Table2[Feb.26],[4]!Table2[Sản phẩm],NXT!$A11) -> 0 | F11: =B11+D11-E11 -> 192 | H11: 0 | I11: =F11+G11-H11 -> 192 | K11: =SUMIFS(INDEX(Detail!$AA:$AL, 0, MATCH(K$1, Detail!$AA$1:$AL$1, 0)), Detail!$J:$J, $A11) -> 0 | L11: =I11+J11-K11 -> 192 | N11: =SUMIFS(INDEX(Detail!$AA:$AL, 0, MATCH(N$1, Detail!$AA$1:$AL$1, 0)), Detail!$J:$J, $A11) -> 0 | O11: =L11+M11-N11 -> 192 | Q11: =SUMIFS(INDEX(Detail!$AA:$AL, 0, MATCH(Q$1, Detail!$AA$1:$AL$1, 0)), Detail!$J:$J, $A11) -> 0 | R11: =O11+P11-Q11 -> 192 | T11: =SUMIFS(INDEX(Detail!$AA:$AL, 0, MATCH(T$1, Detail!$AA$1:$AL$1, 0)), Detail!$J:$J, $A11) -> 0 | U11: =R11+S11-T11 -> 192 | V11: 96 | W11: =SUMIFS(INDEX(Detail!$AA:$AL, 0, MATCH(W$1, Detail!$AA$1:$AL$1, 0)), Detail!$J:$J, $A11) -> 63 | X11: =U11+V11-W11 -> 225 | Z11: =SUMIFS(INDEX(Detail!$AA:$AL, 0, MATCH(Z$1, Detail!$AA$1:$AL$1, 0)), Detail!$J:$J, $A11) -> 63 | AA11: =X11+Y11-Z11 -> 162 | AB11: =96*3 -> 288 | AC11: =SUMIFS(INDEX(Detail!$AA:$AL, 0, MATCH(AC$1, Detail!$AA$1:$AL$1, 0)), Detail!$J:$J, $A11) -> 63 | AD11: =AA11+AB11-AC11 -> 387 | AF11: =SUMIFS(INDEX(Detail!$AA:$AL, 0, MATCH(AF$1, Detail!$AA$1:$AL$1, 0)), Detail!$J:$J, $A11) -> 147 | AG11: =AD11+AE11-AF11 -> 240 | AH11: =96*3 -> 288 | AI11: =SUMIFS(INDEX(Detail!$AA:$AL, 0, MATCH(AI$1, Detail!$AA$1:$AL$1, 0)), Detail!$J:$J, $A11) -> 189 | AJ11: =AG11+AH11-AI11 -> 339 | AL11: =SUMIFS(INDEX(Detail!$AA:$AL, 0, MATCH(AL$1, Detail!$AA$1:$AL$1, 0)), Detail!$J:$J, $A11) -> 189 | AM11: =AJ11+AK11-AL11 -> 150 | AN11: =96*5 -> 480 | AO11: =SUMIFS(INDEX(Detail!$AA:$AL, 0, MATCH(AO$1, Detail!$AA$1:$AL$1, 0)), Detail!$J:$J, $A11) -> 189 | AP11: =AM11+AN11-AO11 -> 441 | AR11: =SUMIFS(INDEX(Detail!$AA:$AL, 0, MATCH(AR$1, Detail!$AA$1:$AL$1, 0)), Detail!$J:$J, $A11) -> 189 | AS11: =AP11+AQ11-AR11 -> 252 | AT11: =96*4 -> 384 | AU11: =SUMIFS(INDEX(Detail!$AA:$AN, 0, MATCH(AU$1, Detail!$AA$1:$AN$1, 0)), Detail!$J:$J, $A11) -> 189 | AV11: =AS11+AT11-AU11 -> 447 | AX11: =SUMIFS(INDEX(Detail!$AA:$AN, 0, MATCH(AX$1, Detail!$AA$1:$AN$1, 0)), Detail!$J:$J, $A11) -> 189 | AY11: =AV11+AW11-AX11 -> 258
A12: Exeol sept 2E 1L | B12: 252 | C12: =INDEX(D12:AZ12, MATCH($C$2, $D$1:$AZ$1, 0))/VLOOKUP(A12,'DK đặt hàng'!A:C,3,FALSE) -> 3 | E12: =SUMIFS([4]!Table2[Feb.26],[4]!Table2[Sản phẩm],NXT!$A12) -> 0 | F12: =B12+D12-E12 -> 252 | H12: 0 | I12: =F12+G12-H12 -> 252 | K12: =SUMIFS(INDEX(Detail!$AA:$AL, 0, MATCH(K$1, Detail!$AA$1:$AL$1, 0)), Detail!$J:$J, $A12) -> 0 | L12: =I12+J12-K12 -> 252 | N12: =SUMIFS(INDEX(Detail!$AA:$AL, 0, MATCH(N$1, Detail!$AA$1:$AL$1, 0)), Detail!$J:$J, $A12) -> 2 | O12: =L12+M12-N12 -> 250 | Q12: =SUMIFS(INDEX(Detail!$AA:$AL, 0, MATCH(Q$1, Detail!$AA$1:$AL$1, 0)), Detail!$J:$J, $A12) -> 2 | R12: =O12+P12-Q12 -> 248 | T12: =SUMIFS(INDEX(Detail!$AA:$AL, 0, MATCH(T$1, Detail!$AA$1:$AL$1, 0)), Detail!$J:$J, $A12) -> 2 | U12: =R12+S12-T12 -> 246 | W12: =SUMIFS(INDEX(Detail!$AA:$AL, 0, MATCH(W$1, Detail!$AA$1:$AL$1, 0)), Detail!$J:$J, $A12) -> 89 | X12: =U12+V12-W12 -> 157 | Y12: =252*3 -> 756 | Z12: =SUMIFS(INDEX(Detail!$AA:$AL, 0, MATCH(Z$1, Detail!$AA$1:$AL$1, 0)), Detail!$J:$J, $A12) -> 231 | AA12: =X12+Y12-Z12 -> 682 | AB12: =252*3 -> 756 | AC12: =SUMIFS(INDEX(Detail!$AA:$AL, 0, MATCH(AC$1, Detail!$AA$1:$AL$1, 0)), Detail!$J:$J, $A12) -> 286 | AD12: =AA12+AB12-AC12 -> 1152 | AF12: =SUMIFS(INDEX(Detail!$AA:$AL, 0, MATCH(AF$1, Detail!$AA$1:$AL$1, 0)), Detail!$J:$J, $A12) -> 322 | AG12: =AD12+AE12-AF12 -> 830 | AH12: =252*4 -> 1008 | AI12: =SUMIFS(INDEX(Detail!$AA:$AL, 0, MATCH(AI$1, Detail!$AA$1:$AL$1, 0)), Detail!$J:$J, $A12) -> 489 | AJ12: =AG12+AH12-AI12 -> 1349 | AL12: =SUMIFS(INDEX(Detail!$AA:$AL, 0, MATCH(AL$1, Detail!$AA$1:$AL$1, 0)), Detail!$J:$J, $A12) -> 568 | AM12: =AJ12+AK12-AL12 -> 781 | AN12: =252*4 -> 1008 | AO12: =SUMIFS(INDEX(Detail!$AA:$AL, 0, MATCH(AO$1, Detail!$AA$1:$AL$1, 0)), Detail!$J:$J, $A12) -> 568 | AP12: =AM12+AN12-AO12 -> 1221 | AR12: =SUMIFS(INDEX(Detail!$AA:$AL, 0, MATCH(AR$1, Detail!$AA$1:$AL$1, 0)), Detail!$J:$J, $A12) -> 568 | AS12: =AP12+AQ12-AR12 -> 653 | AT12: =252*3 -> 756 | AU12: =SUMIFS(INDEX(Detail!$AA:$AN, 0, MATCH(AU$1, Detail!$AA$1:$AN$1, 0)), Detail!$J:$J, $A12) -> 568 | AV12: =AS12+AT12-AU12 -> 841 | AX12: =SUMIFS(INDEX(Detail!$AA:$AN, 0, MATCH(AX$1, Detail!$AA$1:$AN$1, 0)), Detail!$J:$J, $A12) -> 568 | AY12: =AV12+AW12-AX12 -> 273
A13: Exeol sept 2E 5L | B13: 192 | C13: =INDEX(D13:AZ13, MATCH($C$2, $D$1:$AZ$1, 0))/VLOOKUP(A13,'DK đặt hàng'!A:C,3,FALSE) -> 0 | E13: =SUMIFS([4]!Table2[Feb.26],[4]!Table2[Sản phẩm],NXT!$A13) -> 0 | F13: =B13+D13-E13 -> 192 | H13: 0 | I13: =F13+G13-H13 -> 192 | K13: =SUMIFS(INDEX(Detail!$AA:$AL, 0, MATCH(K$1, Detail!$AA$1:$AL$1, 0)), Detail!$J:$J, $A13) -> 0 | L13: =I13+J13-K13 -> 192 | N13: =SUMIFS(INDEX(Detail!$AA:$AL, 0, MATCH(N$1, Detail!$AA$1:$AL$1, 0)), Detail!$J:$J, $A13) -> 0 | O13: =L13+M13-N13 -> 192 | Q13: =SUMIFS(INDEX(Detail!$AA:$AL, 0, MATCH(Q$1, Detail!$AA$1:$AL$1, 0)), Detail!$J:$J, $A13) -> 0 | R13: =O13+P13-Q13 -> 192 | T13: =SUMIFS(INDEX(Detail!$AA:$AL, 0, MATCH(T$1, Detail!$AA$1:$AL$1, 0)), Detail!$J:$J, $A13) -> 0 | U13: =R13+S13-T13 -> 192 | W13: =SUMIFS(INDEX(Detail!$AA:$AL, 0, MATCH(W$1, Detail!$AA$1:$AL$1, 0)), Detail!$J:$J, $A13) -> 6 | X13: =U13+V13-W13 -> 186 | Z13: =SUMIFS(INDEX(Detail!$AA:$AL, 0, MATCH(Z$1, Detail!$AA$1:$AL$1, 0)), Detail!$J:$J, $A13) -> 6 | AA13: =X13+Y13-Z13 -> 180 | AC13: =SUMIFS(INDEX(Detail!$AA:$AL, 0, MATCH(AC$1, Detail!$AA$1:$AL$1, 0)), Detail!$J:$J, $A13) -> 6 | AD13: =AA13+AB13-AC13 -> 174 | AF13: =SUMIFS(INDEX(Detail!$AA:$AL, 0, MATCH(AF$1, Detail!$AA$1:$AL$1, 0)), Detail!$J:$J, $A13) -> 6 | AG13: =AD13+AE13-AF13 -> 168 | AI13: =SUMIFS(INDEX(Detail!$AA:$AL, 0, MATCH(AI$1, Detail!$AA$1:$AL$1, 0)), Detail!$J:$J, $A13) -> 6 | AJ13: =AG13+AH13-AI13 -> 162 | AL13: =SUMIFS(INDEX(Detail!$AA:$AL, 0, MATCH(AL$1, Detail!$AA$1:$AL$1, 0)), Detail!$J:$J, $A13) -> 6 | AM13: =AJ13+AK13-AL13 -> 156 | AO13: =SUMIFS(INDEX(Detail!$AA:$AL, 0, MATCH(AO$1, Detail!$AA$1:$AL$1, 0)), Detail!$J:$J, $A13) -> 6 | AP13: =AM13+AN13-AO13 -> 150 | AR13: =SUMIFS(INDEX(Detail!$AA:$AL, 0, MATCH(AR$1, Detail!$AA$1:$AL$1, 0)), Detail!$J:$J, $A13) -> 6 | AS13: =AP13+AQ13-AR13 -> 144 | AU13: =SUMIFS(INDEX(Detail!$AA:$AN, 0, MATCH(AU$1, Detail!$AA$1:$AN$1, 0)), Detail!$J:$J, $A13) -> 6 | AV13: =AS13+AT13-AU13 -> 138 | AX13: =SUMIFS(INDEX(Detail!$AA:$AN, 0, MATCH(AX$1, Detail!$AA$1:$AN$1, 0)), Detail!$J:$J, $A13) -> 6 | AY13: =AV13+AW13-AX13 -> 132
A14: Exeol OPA 5L | B14: 384 | C14: =INDEX(D14:AZ14, MATCH($C$2, $D$1:$AZ$1, 0))/VLOOKUP(A14,'DK đặt hàng'!A:C,3,FALSE) -> 22 | E14: =SUMIFS([4]!Table2[Feb.26],[4]!Table2[Sản phẩm],NXT!$A14) -> 0 | F14: =B14+D14-E14 -> 384 | H14: 47 | I14: =F14+G14-H14 -> 337 | K14: =SUMIFS(INDEX(Detail!$AA:$AL, 0, MATCH(K$1, Detail!$AA$1:$AL$1, 0)), Detail!$J:$J, $A14) -> 59 | L14: =I14+J14-K14 -> 278 | N14: =SUMIFS(INDEX(Detail!$AA:$AL, 0, MATCH(N$1, Detail!$AA$1:$AL$1, 0)), Detail!$J:$J, $A14) -> 68 | O14: =L14+M14-N14 -> 210 | Q14: =SUMIFS(INDEX(Detail!$AA:$AL, 0, MATCH(Q$1, Detail!$AA$1:$AL$1, 0)), Detail!$J:$J, $A14) -> 123 | R14: =O14+P14-Q14 -> 87 | T14: =SUMIFS(INDEX(Detail!$AA:$AL, 0, MATCH(T$1, Detail!$AA$1:$AL$1, 0)), Detail!$J:$J, $A14) -> 123 | U14: =R14+S14-T14 -> -36 | V14: =96*17 -> 1632 | W14: =SUMIFS(INDEX(Detail!$AA:$AL, 0, MATCH(W$1, Detail!$AA$1:$AL$1, 0)), Detail!$J:$J, $A14) -> 329 | X14: =U14+V14-W14 -> 1267 | Y14: =96*16 -> 1536 | Z14: =SUMIFS(INDEX(Detail!$AA:$AL, 0, MATCH(Z$1, Detail!$AA$1:$AL$1, 0)), Detail!$J:$J, $A14) -> 354 | AA14: =X14+Y14-Z14 -> 2449 | AB14: 96 | AC14: =SUMIFS(INDEX(Detail!$AA:$AL, 0, MATCH(AC$1, Detail!$AA$1:$AL$1, 0)), Detail!$J:$J, $A14) -> 1080 | AD14: =AA14+AB14-AC14 -> 1465 | AE14: =96*22 -> 2112 | AF14: =SUMIFS(INDEX(Detail!$AA:$AL, 0, MATCH(AF$1, Detail!$AA$1:$AL$1, 0)), Detail!$J:$J, $A14) -> 1106 | AG14: =AD14+AE14-AF14 -> 2471 | AI14: =SUMIFS(INDEX(Detail!$AA:$AL, 0, MATCH(AI$1, Detail!$AA$1:$AL$1, 0)), Detail!$J:$J, $A14) -> 1138 | AJ14: =AG14+AH14-AI14 -> 1333 | AK14: =96*22 -> 2112 | AL14: =SUMIFS(INDEX(Detail!$AA:$AL, 0, MATCH(AL$1, Detail!$AA$1:$AL$1, 0)), Detail!$J:$J, $A14) -> 1138 | AM14: =AJ14+AK14-AL14 -> 2307 | AO14: =SUMIFS(INDEX(Detail!$AA:$AL, 0, MATCH(AO$1, Detail!$AA$1:$AL$1, 0)), Detail!$J:$J, $A14) -> 1138 | AP14: =AM14+AN14-AO14 -> 1169 | AQ14: =96*22 -> 2112 | AR14: =SUMIFS(INDEX(Detail!$AA:$AL, 0, MATCH(AR$1, Detail!$AA$1:$AL$1, 0)), Detail!$J:$J, $A14) -> 1138 | AS14: =AP14+AQ14-AR14 -> 2143 | AT14: =96*22 -> 2112 | AU14: =SUMIFS(INDEX(Detail!$AA:$AN, 0, MATCH(AU$1, Detail!$AA$1:$AN$1, 0)), Detail!$J:$J, $A14) -> 1138 | AV14: =AS14+AT14-AU14 -> 3117 | AX14: =SUMIFS(INDEX(Detail!$AA:$AN, 0, MATCH(AX$1, Detail!$AA$1:$AN$1, 0)), Detail!$J:$J, $A14) -> 1138 | AY14: =AV14+AW14-AX14 -> 1979
A15: Exeol GTA 2% 5L | B15: 384 | C15: =INDEX(D15:AZ15, MATCH($C$2, $D$1:$AZ$1, 0))/VLOOKUP(A15,'DK đặt hàng'!A:C,3,FALSE) -> 3 | E15: =SUMIFS([4]!Table2[Feb.26],[4]!Table2[Sản phẩm],NXT!$A15) -> 0 | F15: =B15+D15-E15 -> 384 | H15: 0 | I15: =F15+G15-H15 -> 384 | K15: =SUMIFS(INDEX(Detail!$AA:$AL, 0, MATCH(K$1, Detail!$AA$1:$AL$1, 0)), Detail!$J:$J, $A15) -> 0 | L15: =I15+J15-K15 -> 384 | N15: =SUMIFS(INDEX(Detail!$AA:$AL, 0, MATCH(N$1, Detail!$AA$1:$AL$1, 0)), Detail!$J:$J, $A15) -> 0 | O15: =L15+M15-N15 -> 384 | Q15: =SUMIFS(INDEX(Detail!$AA:$AL, 0, MATCH(Q$1, Detail!$AA$1:$AL$1, 0)), Detail!$J:$J, $A15) -> 9 | R15: =O15+P15-Q15 -> 375 | T15: =SUMIFS(INDEX(Detail!$AA:$AL, 0, MATCH(T$1, Detail!$AA$1:$AL$1, 0)), Detail!$J:$J, $A15) -> 9 | U15: =R15+S15-T15 -> 366 | W15: =SUMIFS(INDEX(Detail!$AA:$AL, 0, MATCH(W$1, Detail!$AA$1:$AL$1, 0)), Detail!$J:$J, $A15) -> 23 | X15: =U15+V15-W15 -> 343 | Z15: =SUMIFS(INDEX(Detail!$AA:$AL, 0, MATCH(Z$1, Detail!$AA$1:$AL$1, 0)), Detail!$J:$J, $A15) -> 30 | AA15: =X15+Y15-Z15 -> 313 | AB15: =96*5 -> 480 | AC15: =SUMIFS(INDEX(Detail!$AA:$AL, 0, MATCH(AC$1, Detail!$AA$1:$AL$1, 0)), Detail!$J:$J, $A15) -> 107 | AD15: =AA15+AB15-AC15 -> 686 | AF15: =SUMIFS(INDEX(Detail!$AA:$AL, 0, MATCH(AF$1, Detail!$AA$1:$AL$1, 0)), Detail!$J:$J, $A15) -> 135 | AG15: =AD15+AE15-AF15 -> 551 | AH15: =96*5 -> 480 | AI15: =SUMIFS(INDEX(Detail!$AA:$AL, 0, MATCH(AI$1, Detail!$AA$1:$AL$1, 0)), Detail!$J:$J, $A15) -> 376 | AJ15: =AG15+AH15-AI15 -> 655 | AL15: =SUMIFS(INDEX(Detail!$AA:$AL, 0, MATCH(AL$1, Detail!$AA$1:$AL$1, 0)), Detail!$J:$J, $A15) -> 426 | AM15: =AJ15+AK15-AL15 -> 229 | AN15: =96*15 -> 1440 | AO15: =SUMIFS(INDEX(Detail!$AA:$AL, 0, MATCH(AO$1, Detail!$AA$1:$AL$1, 0)), Detail!$J:$J, $A15) -> 426 | AP15: =AM15+AN15-AO15 -> 1243 | AR15: =SUMIFS(INDEX(Detail!$AA:$AL, 0, MATCH(AR$1, Detail!$AA$1:$AL$1, 0)), Detail!$J:$J, $A15) -> 426 | AS15: =AP15+AQ15-AR15 -> 817 | AT15: =96*3 -> 288 | AU15: =SUMIFS(INDEX(Detail!$AA:$AN, 0, MATCH(AU$1, Detail!$AA$1:$AN$1, 0)), Detail!$J:$J, $A15) -> 426 | AV15: =AS15+AT15-AU15 -> 679 | AX15: =SUMIFS(INDEX(Detail!$AA:$AN, 0, MATCH(AX$1, Detail!$AA$1:$AN$1, 0)), Detail!$J:$J, $A15) -> 426 | AY15: =AV15+AW15-AX15 -> 253
C16: =SUM(C3:C15) -> 44

Sheet Tồn kho
A1: STT | B1: TÊN HÀNG HÓA | C1: QUY CÁCH THÙNG | D1: ITEM CODE | E1: LOT | F1: DATE | G1: ĐƠN VỊ TÍNH | H1: SỐ LƯỢNG ĐẦU KỲ | I1: 13/11/2025 | J1: 25/11/2025 | K1: CÒN LẠI
A2: 1 | B2: EXEOL STRIPS GTA 2% - Z1 | C2: Thùng 50 ống 100 que thử | D2: AC0174 | E2: 421024 | F2: 31/05/2027 | G2: ống | H2: 50 | I2: 1 | K2: =H2-SUM(I2:J2) -> 49
A3: 2 | B3: EXEOL STRIPS OPA - Z1 | C3: Thùng 50 ống 100 que thử | D3: AC0176 | E3: 4210242 | F3: 30/11/2026 | G3: ống | H3: 50 | I3: 1 | K3: =H3-SUM(I3:J3) -> 49
A4: 3 | B4: EXEOL SURF 30 (BPR) 12X1L | C4: Thùng 12 chai 1L | D4: EXS0034FR | E4: 4S49N4042 | F4: 46123 | G4: chai | H4: 288 | I4: 12 | K4: =H4-SUM(I4:J4) -> 276
A5: 4 | B5: EXEOL SURF 30 (BPR) 4X5L | C5: Thùng 4 can 5L | D5: EXS0035FR | E5: 5S05N0381 | F5: 30/12/2026 | G5: can | H5: 64 | K5: =H5-SUM(I5:J5) -> 64
C6: Thùng 4 can 5L | E6: 5S24N2184 | F6: 46665 | G6: can | H6: 128 | K6: =H6-SUM(I6:J6) -> 128
A7: 5 | B7: EXEOL SURF OPTIMAL 12X750ML | C7: Thùng 12 chai 750mL | D7: EXS0038Z1 | E7: 5S24N2179 | F7: 46635 | G7: chai | H7: 360 | I7: 12 | K7: =H7-SUM(I7:J7) -> 348
A8: 6 | B8: EXEOL WIPES OPTIMAL 12X100 | C8: Thùng 12 hộp 100 miếng | D8: EXS00412F | E8: 5S12N1093 | F8: 17/02/2027 | G8: túi | H8: 360 | I8: 12 | K8: =H8-SUM(I8:J8) -> 348
A9: 7 | B9: EXEOL SEPT FIRST 6X1L DOS 20ML | C9: Thùng 6 chai 1L kèm bơm định lượng 20mL | D9: EXS0043FR-01 | E9: 5S23N2032 | F9: 46451 | G9: chai | H9: 60 | I9: 6 | K9: =H9-SUM(I9:J9) -> 54
C10: Thùng 6 chai 1L kèm bơm định lượng 20mL | E10: 5S28N2509 | F10: 46636 | G10: chai | H10: 192 | K10: =H10-SUM(I10:J10) -> 192
A11: 8 | B11: EXEOL SEPT E2 6X1L DOSEUR 20ML | C11: Thùng 6 chai 1L kèm bơm định lượng 20mL | D11: EXS0046EN | E11: 5S07N0666 | F11: 46692 | G11: chai | H11: 252 | I11: 6 | K11: =H11-SUM(I11:J11) -> 246
A12: 9 | B12: EXEOL CLEAN 4E 6X1L DOSE 20ML | C12: Thùng 6 chai 1L kèm bơm định lượng 20mL | D12: EXS0060Z1 | E12: 5S16N1487 | F12: 23/03/2027 | G12: chai | H12: 252 | I12: 6 | K12: =H12-SUM(I12:J12) -> 246
A13: 10 | B13: EXEOL SEPT E2 4X5L +1 PPE 20ML | C13: Thùng 4 can 5L kèm bơm định lượng20mL | D13: EXS0087EN | E13: 5S25N2268 | F13: 18/05/2027 | G13: can | H13: 192 | K13: =H13-SUM(I13:J13) -> 192
A14: 11 | B14: EXEOL SEPT FIRST 4X5L+1PP 20ML | C14: Thùng 4 can 5L kèm bơm định lượng20mL | D14: EXS0088FR_01 | E14: 5S23N2086 | F14: 46451 | G14: can | H14: 192 | K14: =H14-SUM(I14:J14) -> 192
A15: 12 | B15: EXEOL CLEAN 4E 4X5L+1 PPE 20ML | C15: Thùng 4 can 5L kèm bơm định lượng20mL | D15: EXS0091Z1 | E15: 5S06N0570 | F15: 13/01/2027 | G15: can | H15: 192 | I15: 1 | J15: 1 | K15: =H15-SUM(I15:J15) -> 190
A16: 13 | B16: EXEOL GTA 2% 4X5L | C16: Thùng 4 can 5L | D16: EXS0092Z1 | E16: 5S16N1564 | F16: 16/03/2027 | G16: can | H16: 256 | I16: 4 | K16: =H16-SUM(I16:J16) -> 252
C17: Thùng 4 can 5L | E17: 5S24N2177 | F17: 46696 | G17: can | H17: 128 | K17: =H17-SUM(I17:J17) -> 128
A18: 14 | B18: EXEOL OPA 4X5L | C18: Thùng 4 can 5L | D18: EXS0095Z1 | E18: 5S24N2186 | F18: 46726 | G18: can | H18: 384 | I18: =4 -> 4 | J18: 4 | K18: =H18-SUM(I18:J18) -> 376

Sheet Output
A1: Pháp nhân bán hàng | B1: (Multiple Items)
A3: Row Labels | B3: Sum of Doanh thu ước tính
A4: Exeol OPA 5L | B4: 3.1589437e+09
A5: Bệnh viện An Bình | B5: 686000000
A6: Bệnh Viện Bắc Thăng Long | B6: 13720000
A7: Bệnh viện Bãi Cháy | B7: 357000000
A8: Bệnh viện Đa Khoa An Giang | B8: 238000000
A9: Bệnh viện đa khoa Chương Mỹ | B9: 2482666.7
A10: Bệnh viện đa khoa Đông Anh | B10: 40833333
A11: Bệnh Viện Đa Khoa Đống Đa | B11: 61250000
A12: Bệnh viện Đa Khoa Hà Trung | B12: 32666667
A13: Bệnh viện đa khoa Khu Vực Cù Lao Minh | B13: 57893500
A14: Bệnh viện đa khoa Phú Xuyên | B14: 49000000
A15: Bệnh viện Đa Khoa Sơn Tây | B15: 40833333
... A127: Grand Total | B127: 1.0165997e+10

Sheet Detail
A1: Tháng | B1: Năm | C1: Ngành hàng | D1: KV | E1: Tên PS | F1: Số IB | G1: Tên Khách hàng | H1: Hãng SX | I1: Tên mặt hàng dự thầu | J1: Sodel | K1: Phân nhóm lớn sản phẩm trúng thầu | L1: Phân nhóm nhỏ sản phẩm trúng thầu | M1: Nhập khẩu/ Việt Nam | N1: Dung tích | O1: Số lượng trúng thầu | P1: Đơn giá trúng thầu | Q1: Pháp nhân bán hàng | R1: Đơn giá Sodel | S1: Giá trị trúng thầu | T1: Giá trị trúng thầu (chưa VAT) SODEL | U1: Tỷ lệ trúng thầu | V1: Cấu hình trúng thầu | W1: Số tháng phát sinh | X1: Doanh thu ước tính | Y1: CPK | Z1: %Margin | AA1: Apr.26 | AB1: May.26 | AC1: Jun.26 | AD1: Jul.26 | AE1: Aug.26 | AF1: Sep.26 | AG1: Oct.26 | AH1: Nov.26 | AI1: Dec.26 | AJ1: Jan.27 | AK1: Feb.27 | AL1: Mar.27 | AM1: Apr.27 | AN1: May.27
A2: 4 | B2: 2025 | C2: KSNK | D2: MN | E2: Huỳnh Thị Thùy Linh | F2: IB2400555229 | G2: Bệnh viện Đa Khoa Tỉnh Trà Vinh | H2: Zhivas | I2: Zhivasept Opa | J2: Exeol OPA 5L | K2: Xử lý dụng cụ | L2: KK mức độ cao | M2: Nhập khẩu | N2: 5000 | O2: 100 | P2: 950000 | Q2: Hào Tín | R2: 714000 | S2: 95000000 | T2: =R2*O2 -> 71400000 | U2: 0.09 | V2: Dung dịch khử khuẩn dụng cụ Ortho- Phthalaldehyde 0,55% - Thành phần chính: Ortho-phthalaldehyde 0,55%; pH = 65 - 85, dung dịch pha sẵn (không cần hoạt hóa) - Khử khuẩn mức độ cao trong 5 phút các dụng cụ nội khoa, ngoại khoa, dụng cụ nội soi và dụng cụ không chịu nhiệt - Không mùi, không gây ăn mòn dụng cụ - Phổ diệt khuẩn rộng: diệt khuẩn EN 14561, diệt nấm EN 14562, diệt virus EN 14476, diệt vi khuẩn lao EN 14563 - Tái sử dụng trong 14 ngày (tặng kèm test thử để kiểm tra nồng độ OPA) - Quy cách: Can 5 lít Tiêu chuẩn chất lượng ISO 13485:2016, CE | W2: 11 | X2: =T2*W2/12 -> 65450000 | Y2: =VLOOKUP(Q2,'[3]DATA VALID'!M:O,3,FALSE) -> 0 | Z2: =(R2-VLOOKUP(J2,'[3]DATA VALID'!G:K,5,FALSE))/R2-Y2*1.24 -> 0.31618908 | AB2: =ROUNDUP(Table2[[#This Row],[ Số lượng trúng thầu ]]*Table2[[#This Row],[Số tháng phát sinh]]/12/Table2[[#This Row],[Số tháng phát sinh]],0) -> 9 | AC2: =ROUNDUP(Table2[[#This Row],[ Số lượng trúng thầu ]]*Table2[[#This Row],[Số tháng phát sinh]]/12/Table2[[#This Row],[Số tháng phát sinh]],0) -> 9 | AD2: =ROUNDUP(Table2[[#This Row],[ Số lượng trúng thầu ]]*Table2[[#This Row],[Số tháng phát sinh]]/12/Table2[[#This Row],[Số tháng phát sinh]],0) -> 9 | AE2: =ROUNDUP(Table2[[#This Row],[ Số lượng trúng thầu ]]*Table2[[#This Row],[Số tháng phát sinh]]/12/Table2[[#This Row],[Số tháng phát sinh]],0) -> 9 | AF2: =ROUNDUP(Table2[[#This Row],[ Số lượng trúng thầu ]]*Table2[[#This Row],[Số tháng phát sinh]]/12/Table2[[#This Row],[Số tháng phát sinh]],0) -> 9 | AG2: =ROUNDUP(Table2[[#This Row],[ Số lượng trúng thầu ]]*Table2[[#This Row],[Số tháng phát sinh]]/12/Table2[[#This Row],[Số tháng phát sinh]],0) -> 9 | AH2: =ROUNDUP(Table2[[#This Row],[ Số lượng trúng thầu ]]*Table2[[#This Row],[Số tháng phát sinh]]/12/Table2[[#This Row],[Số tháng phát sinh]],0) -> 9 | AI2: =ROUNDUP(Table2[[#This Row],[ Số lượng trúng thầu ]]*Table2[[#This Row],[Số tháng phát sinh]]/12/Table2[[#This Row],[Số tháng phát sinh]],0) -> 9 | ... AN2: =ROUNDUP(Table2[[#This Row],[ Số lượng trúng thầu ]]*Table2[[#This Row],[Số tháng phát sinh]]/12/Table2[[#This Row],[Số tháng phát sinh]],0) -> 9
A3: 4 | B3: 2025 | C3: KSNK | D3: MN | E3: Huỳnh Thị Thùy Linh | F3: IB2400555229 | G3: Bệnh viện Đa Khoa Tỉnh Trà Vinh | H3: Anios | I3: Anios’Clean Excel D | J3: Exeol sept first 5L | K3: Xử lý dụng cụ | L3: Làm sạch và tiền KK | M3: Nhập khẩu | N3: 5000 | O3: 80 | P3: 1640000 | Q3: Hào Tín | R3: 1218000 | S3: 131200000 | T3: =R3*O3 -> 97440000 | U3: 0.13 | V3: 1 Thành phần: 6,5% Didecyldimethyl ammonium chloride + 0,074% Chlorhexidine digluconate, chất hoạt động bề mặt non-ionic 2 Làm sạch và khử khuẩn dụng cụ y tế Nồng độ sử dụng 05% (25ml trong 5 lít nước) pH = 66 - 76 Thời gian tiếp xúc: từ 5 phút Quy cách: Can 5 lít 3 Hiệu quả diệt khuẩn - Diệt khuẩn EN 14561 - Diệt nấm EN 14562 - Diệt vi khuẩn lao EN 14563 - Diệt virus Vaccinia EN 17111 4 Đạt tiêu chuẩn CE, ISO 13485, ISO 9001 | W3: 11 | X3: =T3*W3/12 -> 89320000 | Y3: =VLOOKUP(Q3,'[3]DATA VALID'!M:O,3,FALSE) -> 0 | Z3: =(R3-VLOOKUP(J3,'[3]DATA VALID'!G:K,5,FALSE))/R3-Y3*1.24 -> 0.49399015 | AB3: =ROUNDUP(Table2[[#This Row],[ Số lượng trúng thầu ]]*Table2[[#This Row],[Số tháng phát sinh]]/12/Table2[[#This Row],[Số tháng phát sinh]],0) -> 7 | AC3: =ROUNDUP(Table2[[#This Row],[ Số lượng trúng thầu ]]*Table2[[#This Row],[Số tháng phát sinh]]/12/Table2[[#This Row],[Số tháng phát sinh]],0) -> 7 | AD3: =ROUNDUP(Table2[[#This Row],[ Số lượng trúng thầu ]]*Table2[[#This Row],[Số tháng phát sinh]]/12/Table2[[#This Row],[Số tháng phát sinh]],0) -> 7 | AE3: =ROUNDUP(Table2[[#This Row],[ Số lượng trúng thầu ]]*Table2[[#This Row],[Số tháng phát sinh]]/12/Table2[[#This Row],[Số tháng phát sinh]],0) -> 7 | AF3: =ROUNDUP(Table2[[#This Row],[ Số lượng trúng thầu ]]*Table2[[#This Row],[Số tháng phát sinh]]/12/Table2[[#This Row],[Số tháng phát sinh]],0) -> 7 | AG3: =ROUNDUP(Table2[[#This Row],[ Số lượng trúng thầu ]]*Table2[[#This Row],[Số tháng phát sinh]]/12/Table2[[#This Row],[Số tháng phát sinh]],0) -> 7 | AH3: =ROUNDUP(Table2[[#This Row],[ Số lượng trúng thầu ]]*Table2[[#This Row],[Số tháng phát sinh]]/12/Table2[[#This Row],[Số tháng phát sinh]],0) -> 7 | AI3: =ROUNDUP(Table2[[#This Row],[ Số lượng trúng thầu ]]*Table2[[#This Row],[Số tháng phát sinh]]/12/Table2[[#This Row],[Số tháng phát sinh]],0) -> 7 | ... AN3: =ROUNDUP(Table2[[#This Row],[ Số lượng trúng thầu ]]*Table2[[#This Row],[Số tháng phát sinh]]/12/Table2[[#This Row],[Số tháng phát sinh]],0) -> 7
